Workbook

Sheet Grid_cost_PEP
A1: PEP Scenario
A2: =Cost_of_ELCgen!A149 -> Calculations | C2: =Cost_of_ELCgen!C149 -> 2020 | D2: =Cost_of_ELCgen!D149 -> 2021 | E2: =Cost_of_ELCgen!E149 -> 2022 | F2: =Cost_of_ELCgen!F149 -> 2023 | G2: =Cost_of_ELCgen!G149 -> 2024 | H2: =Cost_of_ELCgen!H149 -> 2025 | I2: =Cost_of_ELCgen!I149 -> 2026 | J2: =Cost_of_ELCgen!J149 -> 2027 | ... AG2: =Cost_of_ELCgen!AG149 -> 2050
A3: =Cost_of_ELCgen!A150 -> Operating O&M costs | C3: =Cost_of_ELCgen!C150 -> 3983.2703 | D3: =Cost_of_ELCgen!D150 -> 4094.6927 | E3: =Cost_of_ELCgen!E150 -> 4526.0569 | F3: =Cost_of_ELCgen!F150 -> 4486.033 | G3: =Cost_of_ELCgen!G150 -> 4730.4557 | H3: =Cost_of_ELCgen!H150 -> 4390.2596 | I3: =Cost_of_ELCgen!I150 -> 4385.722 | J3: =Cost_of_ELCgen!J150 -> 4587.073 | ... AG3: =Cost_of_ELCgen!AG150 -> 10875.82
A4: =Cost_of_ELCgen!A151 -> Annualized Investment costs | C4: =Cost_of_ELCgen!C151 -> 234.83856 | D4: =Cost_of_ELCgen!D151 -> 756.46065 | E4: =Cost_of_ELCgen!E151 -> 918.84101 | F4: =Cost_of_ELCgen!F151 -> 1006.569 | G4: =Cost_of_ELCgen!G151 -> 1158.3122 | H4: =Cost_of_ELCgen!H151 -> 1276.2681 | I4: =Cost_of_ELCgen!I151 -> 1551.5727 | J4: =Cost_of_ELCgen!J151 -> 1840.1869 | ... AG4: =Cost_of_ELCgen!AG151 -> 11615.939
A5: =Cost_of_ELCgen!A152 -> CO2 costs | C5: =Cost_of_ELCgen!C152 -> 0 | D5: =Cost_of_ELCgen!D152 -> 0 | E5: =Cost_of_ELCgen!E152 -> 0 | F5: =Cost_of_ELCgen!F152 -> 0 | G5: =Cost_of_ELCgen!G152 -> 0 | H5: =Cost_of_ELCgen!H152 -> 0 | I5: =Cost_of_ELCgen!I152 -> 0 | J5: =Cost_of_ELCgen!J152 -> 0 | ... AG5: =Cost_of_ELCgen!AG152 -> 0
A6: =Cost_of_ELCgen!A153 -> Total Costs (Million USD) | C6: =Cost_of_ELCgen!C153 -> 4218.1089 | D6: =Cost_of_ELCgen!D153 -> 4851.1533 | E6: =Cost_of_ELCgen!E153 -> 5444.8979 | F6: =Cost_of_ELCgen!F153 -> 5492.602 | G6: =Cost_of_ELCgen!G153 -> 5888.7679 | H6: =Cost_of_ELCgen!H153 -> 5666.5277 | I6: =Cost_of_ELCgen!I153 -> 5937.2946 | J6: =Cost_of_ELCgen!J153 -> 6427.2599 | ... AG6: =Cost_of_ELCgen!AG153 -> 22491.759
A7: =Cost_of_ELCgen!A154 -> Generation (PJ->GWh), Before Transmission losses | C7: =Cost_of_ELCgen!C154 -> 101777.42 | D7: =Cost_of_ELCgen!D154 -> 106114.28 | E7: =Cost_of_ELCgen!E154 -> 111516.69 | F7: =Cost_of_ELCgen!F154 -> 118003.67 | G7: =Cost_of_ELCgen!G154 -> 126941.67 | H7: =Cost_of_ELCgen!H154 -> 121134.36 | I7: =Cost_of_ELCgen!I154 -> 125377.36 | J7: =Cost_of_ELCgen!J154 -> 132378.08 | ... AG7: =Cost_of_ELCgen!AG154 -> 352549.08
A8: =Cost_of_ELCgen!A155 -> Average electricity cost (USD/kWh) | C8: =Cost_of_ELCgen!C155 -> 0.041444448 | D8: =Cost_of_ELCgen!D155 -> 0.045716311 | E8: =Cost_of_ELCgen!E155 -> 0.048825854 | F8: =Cost_of_ELCgen!F155 -> 0.046546029 | G8: =Cost_of_ELCgen!G155 -> 0.046389559 | H8: =Cost_of_ELCgen!H155 -> 0.046778863 | I8: =Cost_of_ELCgen!I155 -> 0.047355396 | J8: =Cost_of_ELCgen!J155 -> 0.048552296 | ... AG8: =Cost_of_ELCgen!AG155 -> 0.063797525

Sheet Investments_PEP
A1: PEP Scenario
A3: Variable | C3: 2020 | D3: 2021 | E3: 2022 | F3: 2023 | G3: 2024 | H3: 2025 | I3: 2026 | J3: 2027 | K3: 2028 | L3: 2029 | M3: 2030 | N3: 2031 | O3: 2032 | P3: 2033 | Q3: 2034 | R3: 2035 | S3: 2036 | T3: 2037 | U3: 2038 | V3: 2039 | W3: 2040 | X3: 2041 | Y3: 2042 | Z3: 2043 | AA3: 2044 | AB3: 2045 | AC3: 2046 | AD3: 2047 | AE3: 2048 | AF3: 2049 | AG3: 2050
A4: ='Capital Annualized Costs PEP'!A22 -> Total Capital Investments (Million USD) | B4: ='Capital Annualized Costs PEP'!B22 -> 0 | C4: ='Capital Annualized Costs PEP'!C22 -> 4747.952 | D4: ='Capital Annualized Costs PEP'!D22 -> 10006.783 | E4: ='Capital Annualized Costs PEP'!E22 -> 2531.4872 | F4: ='Capital Annualized Costs PEP'!F22 -> 1576.1906 | G4: ='Capital Annualized Costs PEP'!G22 -> 2362.6025 | H4: ='Capital Annualized Costs PEP'!H22 -> 1897.1058 | ... AG4: ='Capital Annualized Costs PEP'!AG22 -> 13589.976
A5: ='Capital Annualized Costs PEP'!A43 -> Total Annualized Investments (Million USD) | B5: ='Capital Annualized Costs PEP'!B43 -> 0 | C5: ='Capital Annualized Costs PEP'!C43 -> 234.83856 | D5: ='Capital Annualized Costs PEP'!D43 -> 756.46065 | E5: ='Capital Annualized Costs PEP'!E43 -> 918.84101 | F5: ='Capital Annualized Costs PEP'!F43 -> 1006.569 | G5: ='Capital Annualized Costs PEP'!G43 -> 1158.3122 | H5: ='Capital Annualized Costs PEP'!H43 -> 1276.2681 | ... AG5: ='Capital Annualized Costs PEP'!AG43 -> 11615.939

Sheet Capital Annualized Costs PEP
A1: PEP Scenario
A3: Capital Investments (M.USD) | C3: 2020 | D3: 2021 | E3: 2022 | F3: 2023 | G3: 2024 | H3: 2025 | I3: 2026 | J3: 2027 | K3: 2028 | L3: 2029 | M3: 2030 | N3: 2031 | O3: 2032 | P3: 2033 | Q3: 2034 | R3: 2035 | S3: 2036 | T3: 2037 | U3: 2038 | V3: 2039 | W3: 2040 | X3: 2041 | Y3: 2042 | Z3: 2043 | AA3: 2044 | AB3: 2045 | AC3: 2046 | AD3: 2047 | AE3: 2048 | AF3: 2049 | AG3: 2050
A4: PHL_POW_CHP_BIOM_OLD | C4: =SUMIFS(Capital_Investments!C$2:C$10000,Capital_Investments!$B$2:$B$10000,$A4) -> 0 | D4: =SUMIFS(Capital_Investments!D$2:D$10000,Capital_Investments!$B$2:$B$10000,$A4) -> 0 | E4: =SUMIFS(Capital_Investments!E$2:E$10000,Capital_Investments!$B$2:$B$10000,$A4) -> 369 | F4: =SUMIFS(Capital_Investments!F$2:F$10000,Capital_Investments!$B$2:$B$10000,$A4) -> 27 | G4: =SUMIFS(Capital_Investments!G$2:G$10000,Capital_Investments!$B$2:$B$10000,$A4) -> 44.55 | H4: =SUMIFS(Capital_Investments!H$2:H$10000,Capital_Investments!$B$2:$B$10000,$A4) -> 0 | I4: =SUMIFS(Capital_Investments!I$2:I$10000,Capital_Investments!$B$2:$B$10000,$A4) -> 0 | J4: =SUMIFS(Capital_Investments!J$2:J$10000,Capital_Investments!$B$2:$B$10000,$A4) -> 0 | ... AG4: =SUMIFS(Capital_Investments!AG$2:AG$10000,Capital_Investments!$B$2:$B$10000,$A4) -> 0
A5: PHL_POW_CHP_COAL_OLD | C5: =SUMIFS(Capital_Investments!C$2:C$10000,Capital_Investments!$B$2:$B$10000,$A5) -> 0 | D5: =SUMIFS(Capital_Investments!D$2:D$10000,Capital_Investments!$B$2:$B$10000,$A5) -> 0 | E5: =SUMIFS(Capital_Investments!E$2:E$10000,Capital_Investments!$B$2:$B$10000,$A5) -> 0 | F5: =SUMIFS(Capital_Investments!F$2:F$10000,Capital_Investments!$B$2:$B$10000,$A5) -> 0 | G5: =SUMIFS(Capital_Investments!G$2:G$10000,Capital_Investments!$B$2:$B$10000,$A5) -> 0 | H5: =SUMIFS(Capital_Investments!H$2:H$10000,Capital_Investments!$B$2:$B$10000,$A5) -> 0 | I5: =SUMIFS(Capital_Investments!I$2:I$10000,Capital_Investments!$B$2:$B$10000,$A5) -> 0 | J5: =SUMIFS(Capital_Investments!J$2:J$10000,Capital_Investments!$B$2:$B$10000,$A5) -> 0 | ... AG5: =SUMIFS(Capital_Investments!AG$2:AG$10000,Capital_Investments!$B$2:$B$10000,$A5) -> 0
A6: PHL_POW_GEO_OLD | C6: =SUMIFS(Capital_Investments!C$2:C$10000,Capital_Investments!$B$2:$B$10000,$A6) -> 0 | D6: =SUMIFS(Capital_Investments!D$2:D$10000,Capital_Investments!$B$2:$B$10000,$A6) -> 0 | E6: =SUMIFS(Capital_Investments!E$2:E$10000,Capital_Investments!$B$2:$B$10000,$A6) -> 16.28 | F6: =SUMIFS(Capital_Investments!F$2:F$10000,Capital_Investments!$B$2:$B$10000,$A6) -> 1236.7766 | G6: =SUMIFS(Capital_Investments!G$2:G$10000,Capital_Investments!$B$2:$B$10000,$A6) -> 29.5789 | H6: =SUMIFS(Capital_Investments!H$2:H$10000,Capital_Investments!$B$2:$B$10000,$A6) -> 157.08 | I6: =SUMIFS(Capital_Investments!I$2:I$10000,Capital_Investments!$B$2:$B$10000,$A6) -> 3722.5143 | J6: =SUMIFS(Capital_Investments!J$2:J$10000,Capital_Investments!$B$2:$B$10000,$A6) -> 0 | ... AG6: =SUMIFS(Capital_Investments!AG$2:AG$10000,Capital_Investments!$B$2:$B$10000,$A6) -> 0
A7: PHL_POW_PP_BIOM_CCS | C7: =SUMIFS(Capital_Investments!C$2:C$10000,Capital_Investments!$B$2:$B$10000,$A7) -> 0 | D7: =SUMIFS(Capital_Investments!D$2:D$10000,Capital_Investments!$B$2:$B$10000,$A7) -> 0 | E7: =SUMIFS(Capital_Investments!E$2:E$10000,Capital_Investments!$B$2:$B$10000,$A7) -> 0 | F7: =SUMIFS(Capital_Investments!F$2:F$10000,Capital_Investments!$B$2:$B$10000,$A7) -> 0 | G7: =SUMIFS(Capital_Investments!G$2:G$10000,Capital_Investments!$B$2:$B$10000,$A7) -> 0 | H7: =SUMIFS(Capital_Investments!H$2:H$10000,Capital_Investments!$B$2:$B$10000,$A7) -> 0 | I7: =SUMIFS(Capital_Investments!I$2:I$10000,Capital_Investments!$B$2:$B$10000,$A7) -> 0 | J7: =SUMIFS(Capital_Investments!J$2:J$10000,Capital_Investments!$B$2:$B$10000,$A7) -> 0 | ... AG7: =SUMIFS(Capital_Investments!AG$2:AG$10000,Capital_Investments!$B$2:$B$10000,$A7) -> 0
A8: PHL_POW_PP_COAL | C8: =SUMIFS(Capital_Investments!C$2:C$10000,Capital_Investments!$B$2:$B$10000,$A8) -> 0 | D8: =SUMIFS(Capital_Investments!D$2:D$10000,Capital_Investments!$B$2:$B$10000,$A8) -> 1595 | E8: =SUMIFS(Capital_Investments!E$2:E$10000,Capital_Investments!$B$2:$B$10000,$A8) -> 1692.68 | F8: =SUMIFS(Capital_Investments!F$2:F$10000,Capital_Investments!$B$2:$B$10000,$A8) -> 0 | G8: =SUMIFS(Capital_Investments!G$2:G$10000,Capital_Investments!$B$2:$B$10000,$A8) -> 1320 | H8: =SUMIFS(Capital_Investments!H$2:H$10000,Capital_Investments!$B$2:$B$10000,$A8) -> 0 | I8: =SUMIFS(Capital_Investments!I$2:I$10000,Capital_Investments!$B$2:$B$10000,$A8) -> 0 | J8: =SUMIFS(Capital_Investments!J$2:J$10000,Capital_Investments!$B$2:$B$10000,$A8) -> 3254.5245 | ... AG8: =SUMIFS(Capital_Investments!AG$2:AG$10000,Capital_Investments!$B$2:$B$10000,$A8) -> 0
A9: PHL_POW_PP_COAL_CCS | C9: =SUMIFS(Capital_Investments!C$2:C$10000,Capital_Investments!$B$2:$B$10000,$A9) -> 0 | D9: =SUMIFS(Capital_Investments!D$2:D$10000,Capital_Investments!$B$2:$B$10000,$A9) -> 0 | E9: =SUMIFS(Capital_Investments!E$2:E$10000,Capital_Investments!$B$2:$B$10000,$A9) -> 0 | F9: =SUMIFS(Capital_Investments!F$2:F$10000,Capital_Investments!$B$2:$B$10000,$A9) -> 0 | G9: =SUMIFS(Capital_Investments!G$2:G$10000,Capital_Investments!$B$2:$B$10000,$A9) -> 0 | H9: =SUMIFS(Capital_Investments!H$2:H$10000,Capital_Investments!$B$2:$B$10000,$A9) -> 0 | I9: =SUMIFS(Capital_Investments!I$2:I$10000,Capital_Investments!$B$2:$B$10000,$A9) -> 0 | J9: =SUMIFS(Capital_Investments!J$2:J$10000,Capital_Investments!$B$2:$B$10000,$A9) -> 0 | ... AG9: =SUMIFS(Capital_Investments!AG$2:AG$10000,Capital_Investments!$B$2:$B$10000,$A9) -> 0
A10: PHL_POW_PP_H2 | C10: =SUMIFS(Capital_Investments!C$2:C$10000,Capital_Investments!$B$2:$B$10000,$A10) -> 0 | D10: =SUMIFS(Capital_Investments!D$2:D$10000,Capital_Investments!$B$2:$B$10000,$A10) -> 0 | E10: =SUMIFS(Capital_Investments!E$2:E$10000,Capital_Investments!$B$2:$B$10000,$A10) -> 0 | F10: =SUMIFS(Capital_Investments!F$2:F$10000,Capital_Investments!$B$2:$B$10000,$A10) -> 0 | G10: =SUMIFS(Capital_Investments!G$2:G$10000,Capital_Investments!$B$2:$B$10000,$A10) -> 0 | H10: =SUMIFS(Capital_Investments!H$2:H$10000,Capital_Investments!$B$2:$B$10000,$A10) -> 0 | I10: =SUMIFS(Capital_Investments!I$2:I$10000,Capital_Investments!$B$2:$B$10000,$A10) -> 0 | J10: =SUMIFS(Capital_Investments!J$2:J$10000,Capital_Investments!$B$2:$B$10000,$A10) -> 0 | ... AG10: =SUMIFS(Capital_Investments!AG$2:AG$10000,Capital_Investments!$B$2:$B$10000,$A10) -> 0
A11: PHL_POW_PP_HY_LA | C11: =SUMIFS(Capital_Investments!C$2:C$10000,Capital_Investments!$B$2:$B$10000,$A11) -> 4389.9544 | D11: =SUMIFS(Capital_Investments!D$2:D$10000,Capital_Investments!$B$2:$B$10000,$A11) -> 7663.7159 | E11: =SUMIFS(Capital_Investments!E$2:E$10000,Capital_Investments!$B$2:$B$10000,$A11) -> 47.7 | F11: =SUMIFS(Capital_Investments!F$2:F$10000,Capital_Investments!$B$2:$B$10000,$A11) -> 140.4 | G11: =SUMIFS(Capital_Investments!G$2:G$10000,Capital_Investments!$B$2:$B$10000,$A11) -> 105.6 | H11: =SUMIFS(Capital_Investments!H$2:H$10000,Capital_Investments!$B$2:$B$10000,$A11) -> 0 | I11: =SUMIFS(Capital_Investments!I$2:I$10000,Capital_Investments!$B$2:$B$10000,$A11) -> 0 | J11: =SUMIFS(Capital_Investments!J$2:J$10000,Capital_Investments!$B$2:$B$10000,$A11) -> 0 | ... AG11: =SUMIFS(Capital_Investments!AG$2:AG$10000,Capital_Investments!$B$2:$B$10000,$A11) -> 0
A12: PHL_POW_PP_NGCC | C12: =SUMIFS(Capital_Investments!C$2:C$10000,Capital_Investments!$B$2:$B$10000,$A12) -> 0 | D12: =SUMIFS(Capital_Investments!D$2:D$10000,Capital_Investments!$B$2:$B$10000,$A12) -> 0 | E12: =SUMIFS(Capital_Investments!E$2:E$10000,Capital_Investments!$B$2:$B$10000,$A12) -> 0 | F12: =SUMIFS(Capital_Investments!F$2:F$10000,Capital_Investments!$B$2:$B$10000,$A12) -> 0 | G12: =SUMIFS(Capital_Investments!G$2:G$10000,Capital_Investments!$B$2:$B$10000,$A12) -> 0 | H12: =SUMIFS(Capital_Investments!H$2:H$10000,Capital_Investments!$B$2:$B$10000,$A12) -> 1056 | I12: =SUMIFS(Capital_Investments!I$2:I$10000,Capital_Investments!$B$2:$B$10000,$A12) -> 0 | J12: =SUMIFS(Capital_Investments!J$2:J$10000,Capital_Investments!$B$2:$B$10000,$A12) -> 0 | ... AG12: =SUMIFS(Capital_Investments!AG$2:AG$10000,Capital_Investments!$B$2:$B$10000,$A12) -> 2024.2701
A13: PHL_POW_PP_NGCC_CCS | C13: =SUMIFS(Capital_Investments!C$2:C$10000,Capital_Investments!$B$2:$B$10000,$A13) -> 0 | D13: =SUMIFS(Capital_Investments!D$2:D$10000,Capital_Investments!$B$2:$B$10000,$A13) -> 0 | E13: =SUMIFS(Capital_Investments!E$2:E$10000,Capital_Investments!$B$2:$B$10000,$A13) -> 0 | F13: =SUMIFS(Capital_Investments!F$2:F$10000,Capital_Investments!$B$2:$B$10000,$A13) -> 0 | G13: =SUMIFS(Capital_Investments!G$2:G$10000,Capital_Investments!$B$2:$B$10000,$A13) -> 0 | H13: =SUMIFS(Capital_Investments!H$2:H$10000,Capital_Investments!$B$2:$B$10000,$A13) -> 0 | I13: =SUMIFS(Capital_Investments!I$2:I$10000,Capital_Investments!$B$2:$B$10000,$A13) -> 0 | J13: =SUMIFS(Capital_Investments!J$2:J$10000,Capital_Investments!$B$2:$B$10000,$A13) -> 0 | ... AG13: =SUMIFS(Capital_Investments!AG$2:AG$10000,Capital_Investments!$B$2:$B$10000,$A13) -> 0
A14: PHL_POW_PP_NU | C14: =SUMIFS(Capital_Investments!C$2:C$10000,Capital_Investments!$B$2:$B$10000,$A14) -> 0 | D14: =SUMIFS(Capital_Investments!D$2:D$10000,Capital_Investments!$B$2:$B$10000,$A14) -> 0 | E14: =SUMIFS(Capital_Investments!E$2:E$10000,Capital_Investments!$B$2:$B$10000,$A14) -> 0 | F14: =SUMIFS(Capital_Investments!F$2:F$10000,Capital_Investments!$B$2:$B$10000,$A14) -> 0 | G14: =SUMIFS(Capital_Investments!G$2:G$10000,Capital_Investments!$B$2:$B$10000,$A14) -> 0 | H14: =SUMIFS(Capital_Investments!H$2:H$10000,Capital_Investments!$B$2:$B$10000,$A14) -> 0 | I14: =SUMIFS(Capital_Investments!I$2:I$10000,Capital_Investments!$B$2:$B$10000,$A14) -> 0 | J14: =SUMIFS(Capital_Investments!J$2:J$10000,Capital_Investments!$B$2:$B$10000,$A14) -> 0 | ... AG14: =SUMIFS(Capital_Investments!AG$2:AG$10000,Capital_Investments!$B$2:$B$10000,$A14) -> 0
A15: PHL_POW_PP_NUSMR | C15: =SUMIFS(Capital_Investments!C$2:C$10000,Capital_Investments!$B$2:$B$10000,$A15) -> 0 | D15: =SUMIFS(Capital_Investments!D$2:D$10000,Capital_Investments!$B$2:$B$10000,$A15) -> 0 | E15: =SUMIFS(Capital_Investments!E$2:E$10000,Capital_Investments!$B$2:$B$10000,$A15) -> 0 | F15: =SUMIFS(Capital_Investments!F$2:F$10000,Capital_Investments!$B$2:$B$10000,$A15) -> 0 | G15: =SUMIFS(Capital_Investments!G$2:G$10000,Capital_Investments!$B$2:$B$10000,$A15) -> 0 | H15: =SUMIFS(Capital_Investments!H$2:H$10000,Capital_Investments!$B$2:$B$10000,$A15) -> 0 | I15: =SUMIFS(Capital_Investments!I$2:I$10000,Capital_Investments!$B$2:$B$10000,$A15) -> 0 | J15: =SUMIFS(Capital_Investments!J$2:J$10000,Capital_Investments!$B$2:$B$10000,$A15) -> 0 | ... AG15: =SUMIFS(Capital_Investments!AG$2:AG$10000,Capital_Investments!$B$2:$B$10000,$A15) -> 5132.753
... A21: PHL_POW_TD | C21: =SUMIFS(Capital_Investments!C$2:C$10000,Capital_Investments!$B$2:$B$10000,$A21) -> 0 | D21: =SUMIFS(Capital_Investments!D$2:D$10000,Capital_Investments!$B$2:$B$10000,$A21) -> 0 | E21: =SUMIFS(Capital_Investments!E$2:E$10000,Capital_Investments!$B$2:$B$10000,$A21) -> 0 | F21: =SUMIFS(Capital_Investments!F$2:F$10000,Capital_Investments!$B$2:$B$10000,$A21) -> 0 | G21: =SUMIFS(Capital_Investments!G$2:G$10000,Capital_Investments!$B$2:$B$10000,$A21) -> 0 | H21: =SUMIFS(Capital_Investments!H$2:H$10000,Capital_Investments!$B$2:$B$10000,$A21) -> 459.6972 | I21: =SUMIFS(Capital_Investments!I$2:I$10000,Capital_Investments!$B$2:$B$10000,$A21) -> 1316.7722 | J21: =SUMIFS(Capital_Investments!J$2:J$10000,Capital_Investments!$B$2:$B$10000,$A21) -> 1316.7722 | ... AG21: =SUMIFS(Capital_Investments!AG$2:AG$10000,Capital_Investments!$B$2:$B$10000,$A21) -> 3107.0751
A22: Total Capital Investments (Million USD) | C22: =SUM(C4:C21) -> 4747.952 | D22: =SUM(D4:D21) -> 10006.783 | E22: =SUM(E4:E21) -> 2531.4872 | F22: =SUM(F4:F21) -> 1576.1906 | G22: =SUM(G4:G21) -> 2362.6025 | H22: =SUM(H4:H21) -> 1897.1058 | I22: =SUM(I4:I21) -> 5039.2865 | J22: =SUM(J4:J21) -> 4571.2967 | ... AG22: =SUM(AG4:AG21) -> 13589.976
A24: Annualized Investment Cost (M.USD) | C24: 2020 | D24: 2021 | E24: 2022 | F24: 2023 | G24: 2024 | H24: 2025 | I24: 2026 | J24: 2027 | K24: 2028 | L24: 2029 | M24: 2030 | N24: 2031 | O24: 2032 | P24: 2033 | Q24: 2034 | R24: 2035 | S24: 2036 | T24: 2037 | U24: 2038 | V24: 2039 | W24: 2040 | X24: 2041 | Y24: 2042 | Z24: 2043 | AA24: 2044 | AB24: 2045 | AC24: 2046 | AD24: 2047 | AE24: 2048 | AF24: 2049 | AG24: 2050
A25: PHL_POW_CHP_BIOM_OLD | C25: =SUMIFS(Annualized_Investments!C$2:C$9991,Annualized_Investments!$B$2:$B$9991,$A25) -> 0 | D25: =SUMIFS(Annualized_Investments!D$2:D$9991,Annualized_Investments!$B$2:$B$9991,$A25) -> 0 | E25: =SUMIFS(Annualized_Investments!E$2:E$9991,Annualized_Investments!$B$2:$B$9991,$A25) -> 20.480611 | F25: =SUMIFS(Annualized_Investments!F$2:F$9991,Annualized_Investments!$B$2:$B$9991,$A25) -> 21.979192 | G25: =SUMIFS(Annualized_Investments!G$2:G$9991,Annualized_Investments!$B$2:$B$9991,$A25) -> 24.451851 | H25: =SUMIFS(Annualized_Investments!H$2:H$9991,Annualized_Investments!$B$2:$B$9991,$A25) -> 24.451851 | I25: =SUMIFS(Annualized_Investments!I$2:I$9991,Annualized_Investments!$B$2:$B$9991,$A25) -> 24.451851 | J25: =SUMIFS(Annualized_Investments!J$2:J$9991,Annualized_Investments!$B$2:$B$9991,$A25) -> 24.451851 | ... AG25: =SUMIFS(Annualized_Investments!AG$2:AG$9991,Annualized_Investments!$B$2:$B$9991,$A25) -> 24.451851
A26: PHL_POW_CHP_COAL_OLD | C26: =SUMIFS(Annualized_Investments!C$2:C$9991,Annualized_Investments!$B$2:$B$9991,$A26) -> 0 | D26: =SUMIFS(Annualized_Investments!D$2:D$9991,Annualized_Investments!$B$2:$B$9991,$A26) -> 0 | E26: =SUMIFS(Annualized_Investments!E$2:E$9991,Annualized_Investments!$B$2:$B$9991,$A26) -> 0 | F26: =SUMIFS(Annualized_Investments!F$2:F$9991,Annualized_Investments!$B$2:$B$9991,$A26) -> 0 | G26: =SUMIFS(Annualized_Investments!G$2:G$9991,Annualized_Investments!$B$2:$B$9991,$A26) -> 0 | H26: =SUMIFS(Annualized_Investments!H$2:H$9991,Annualized_Investments!$B$2:$B$9991,$A26) -> 0 | I26: =SUMIFS(Annualized_Investments!I$2:I$9991,Annualized_Investments!$B$2:$B$9991,$A26) -> 0 | J26: =SUMIFS(Annualized_Investments!J$2:J$9991,Annualized_Investments!$B$2:$B$9991,$A26) -> 0 | ... AG26: =SUMIFS(Annualized_Investments!AG$2:AG$9991,Annualized_Investments!$B$2:$B$9991,$A26) -> 0
A27: PHL_POW_GEO_OLD | C27: =SUMIFS(Annualized_Investments!C$2:C$9991,Annualized_Investments!$B$2:$B$9991,$A27) -> 0 | D27: =SUMIFS(Annualized_Investments!D$2:D$9991,Annualized_Investments!$B$2:$B$9991,$A27) -> 0 | E27: =SUMIFS(Annualized_Investments!E$2:E$9991,Annualized_Investments!$B$2:$B$9991,$A27) -> 0.90358901 | F27: =SUMIFS(Annualized_Investments!F$2:F$9991,Annualized_Investments!$B$2:$B$9991,$A27) -> 69.548414 | G27: =SUMIFS(Annualized_Investments!G$2:G$9991,Annualized_Investments!$B$2:$B$9991,$A27) -> 71.190132 | H27: =SUMIFS(Annualized_Investments!H$2:H$9991,Annualized_Investments!$B$2:$B$9991,$A27) -> 79.908545 | I27: =SUMIFS(Annualized_Investments!I$2:I$9991,Annualized_Investments!$B$2:$B$9991,$A27) -> 286.5193 | J27: =SUMIFS(Annualized_Investments!J$2:J$9991,Annualized_Investments!$B$2:$B$9991,$A27) -> 286.5193 | ... AG27: =SUMIFS(Annualized_Investments!AG$2:AG$9991,Annualized_Investments!$B$2:$B$9991,$A27) -> 955.8587
A28: PHL_POW_PP_BIOM_CCS | C28: =SUMIFS(Annualized_Investments!C$2:C$9991,Annualized_Investments!$B$2:$B$9991,$A28) -> 0 | D28: =SUMIFS(Annualized_Investments!D$2:D$9991,Annualized_Investments!$B$2:$B$9991,$A28) -> 0 | E28: =SUMIFS(Annualized_Investments!E$2:E$9991,Annualized_Investments!$B$2:$B$9991,$A28) -> 0 | F28: =SUMIFS(Annualized_Investments!F$2:F$9991,Annualized_Investments!$B$2:$B$9991,$A28) -> 0 | G28: =SUMIFS(Annualized_Investments!G$2:G$9991,Annualized_Investments!$B$2:$B$9991,$A28) -> 0 | H28: =SUMIFS(Annualized_Investments!H$2:H$9991,Annualized_Investments!$B$2:$B$9991,$A28) -> 0 | I28: =SUMIFS(Annualized_Investments!I$2:I$9991,Annualized_Investments!$B$2:$B$9991,$A28) -> 0 | J28: =SUMIFS(Annualized_Investments!J$2:J$9991,Annualized_Investments!$B$2:$B$9991,$A28) -> 0 | ... AG28: =SUMIFS(Annualized_Investments!AG$2:AG$9991,Annualized_Investments!$B$2:$B$9991,$A28) -> 0
A29: PHL_POW_PP_COAL | C29: =SUMIFS(Annualized_Investments!C$2:C$9991,Annualized_Investments!$B$2:$B$9991,$A29) -> 0 | D29: =SUMIFS(Annualized_Investments!D$2:D$9991,Annualized_Investments!$B$2:$B$9991,$A29) -> 107.78016 | E29: =SUMIFS(Annualized_Investments!E$2:E$9991,Annualized_Investments!$B$2:$B$9991,$A29) -> 222.16093 | F29: =SUMIFS(Annualized_Investments!F$2:F$9991,Annualized_Investments!$B$2:$B$9991,$A29) -> 222.16093 | G29: =SUMIFS(Annualized_Investments!G$2:G$9991,Annualized_Investments!$B$2:$B$9991,$A29) -> 311.3583 | H29: =SUMIFS(Annualized_Investments!H$2:H$9991,Annualized_Investments!$B$2:$B$9991,$A29) -> 311.3583 | I29: =SUMIFS(Annualized_Investments!I$2:I$9991,Annualized_Investments!$B$2:$B$9991,$A29) -> 311.3583 | J29: =SUMIFS(Annualized_Investments!J$2:J$9991,Annualized_Investments!$B$2:$B$9991,$A29) -> 531.27879 | ... AG29: =SUMIFS(Annualized_Investments!AG$2:AG$9991,Annualized_Investments!$B$2:$B$9991,$A29) -> 1685.1947
A30: PHL_POW_PP_COAL_CCS | C30: =SUMIFS(Annualized_Investments!C$2:C$9991,Annualized_Investments!$B$2:$B$9991,$A30) -> 0 | D30: =SUMIFS(Annualized_Investments!D$2:D$9991,Annualized_Investments!$B$2:$B$9991,$A30) -> 0 | E30: =SUMIFS(Annualized_Investments!E$2:E$9991,Annualized_Investments!$B$2:$B$9991,$A30) -> 0 | F30: =SUMIFS(Annualized_Investments!F$2:F$9991,Annualized_Investments!$B$2:$B$9991,$A30) -> 0 | G30: =SUMIFS(Annualized_Investments!G$2:G$9991,Annualized_Investments!$B$2:$B$9991,$A30) -> 0 | H30: =SUMIFS(Annualized_Investments!H$2:H$9991,Annualized_Investments!$B$2:$B$9991,$A30) -> 0 | I30: =SUMIFS(Annualized_Investments!I$2:I$9991,Annualized_Investments!$B$2:$B$9991,$A30) -> 0 | J30: =SUMIFS(Annualized_Investments!J$2:J$9991,Annualized_Investments!$B$2:$B$9991,$A30) -> 0 | ... AG30: =SUMIFS(Annualized_Investments!AG$2:AG$9991,Annualized_Investments!$B$2:$B$9991,$A30) -> 0
A31: PHL_POW_PP_H2 | C31: =SUMIFS(Annualized_Investments!C$2:C$9991,Annualized_Investments!$B$2:$B$9991,$A31) -> 0 | D31: =SUMIFS(Annualized_Investments!D$2:D$9991,Annualized_Investments!$B$2:$B$9991,$A31) -> 0 | E31: =SUMIFS(Annualized_Investments!E$2:E$9991,Annualized_Investments!$B$2:$B$9991,$A31) -> 0 | F31: =SUMIFS(Annualized_Investments!F$2:F$9991,Annualized_Investments!$B$2:$B$9991,$A31) -> 0 | G31: =SUMIFS(Annualized_Investments!G$2:G$9991,Annualized_Investments!$B$2:$B$9991,$A31) -> 0 | H31: =SUMIFS(Annualized_Investments!H$2:H$9991,Annualized_Investments!$B$2:$B$9991,$A31) -> 0 | I31: =SUMIFS(Annualized_Investments!I$2:I$9991,Annualized_Investments!$B$2:$B$9991,$A31) -> 0 | J31: =SUMIFS(Annualized_Investments!J$2:J$9991,Annualized_Investments!$B$2:$B$9991,$A31) -> 0 | ... AG31: =SUMIFS(Annualized_Investments!AG$2:AG$9991,Annualized_Investments!$B$2:$B$9991,$A31) -> 0
A32: PHL_POW_PP_HY_LA | C32: =SUMIFS(Annualized_Investments!C$2:C$9991,Annualized_Investments!$B$2:$B$9991,$A32) -> 210.64731 | D32: =SUMIFS(Annualized_Investments!D$2:D$9991,Annualized_Investments!$B$2:$B$9991,$A32) -> 578.3826 | E32: =SUMIFS(Annualized_Investments!E$2:E$9991,Annualized_Investments!$B$2:$B$9991,$A32) -> 580.67144 | F32: =SUMIFS(Annualized_Investments!F$2:F$9991,Annualized_Investments!$B$2:$B$9991,$A32) -> 587.40838 | G32: =SUMIFS(Annualized_Investments!G$2:G$9991,Annualized_Investments!$B$2:$B$9991,$A32) -> 592.47549 | H32: =SUMIFS(Annualized_Investments!H$2:H$9991,Annualized_Investments!$B$2:$B$9991,$A32) -> 592.47549 | I32: =SUMIFS(Annualized_Investments!I$2:I$9991,Annualized_Investments!$B$2:$B$9991,$A32) -> 592.47549 | J32: =SUMIFS(Annualized_Investments!J$2:J$9991,Annualized_Investments!$B$2:$B$9991,$A32) -> 592.47549 | ... AG32: =SUMIFS(Annualized_Investments!AG$2:AG$9991,Annualized_Investments!$B$2:$B$9991,$A32) -> 592.47549
A33: PHL_POW_PP_NGCC | C33: =SUMIFS(Annualized_Investments!C$2:C$9991,Annualized_Investments!$B$2:$B$9991,$A33) -> 0 | D33: =SUMIFS(Annualized_Investments!D$2:D$9991,Annualized_Investments!$B$2:$B$9991,$A33) -> 0 | E33: =SUMIFS(Annualized_Investments!E$2:E$9991,Annualized_Investments!$B$2:$B$9991,$A33) -> 0 | F33: =SUMIFS(Annualized_Investments!F$2:F$9991,Annualized_Investments!$B$2:$B$9991,$A33) -> 0 | G33: =SUMIFS(Annualized_Investments!G$2:G$9991,Annualized_Investments!$B$2:$B$9991,$A33) -> 0 | H33: =SUMIFS(Annualized_Investments!H$2:H$9991,Annualized_Investments!$B$2:$B$9991,$A33) -> 71.3579 | I33: =SUMIFS(Annualized_Investments!I$2:I$9991,Annualized_Investments!$B$2:$B$9991,$A33) -> 71.3579 | J33: =SUMIFS(Annualized_Investments!J$2:J$9991,Annualized_Investments!$B$2:$B$9991,$A33) -> 71.3579 | ... AG33: =SUMIFS(Annualized_Investments!AG$2:AG$9991,Annualized_Investments!$B$2:$B$9991,$A33) -> 815.71985
A34: PHL_POW_PP_NGCC_CCS | C34: =SUMIFS(Annualized_Investments!C$2:C$9991,Annualized_Investments!$B$2:$B$9991,$A34) -> 0 | D34: =SUMIFS(Annualized_Investments!D$2:D$9991,Annualized_Investments!$B$2:$B$9991,$A34) -> 0 | E34: =SUMIFS(Annualized_Investments!E$2:E$9991,Annualized_Investments!$B$2:$B$9991,$A34) -> 0 | F34: =SUMIFS(Annualized_Investments!F$2:F$9991,Annualized_Investments!$B$2:$B$9991,$A34) -> 0 | G34: =SUMIFS(Annualized_Investments!G$2:G$9991,Annualized_Investments!$B$2:$B$9991,$A34) -> 0 | H34: =SUMIFS(Annualized_Investments!H$2:H$9991,Annualized_Investments!$B$2:$B$9991,$A34) -> 0 | I34: =SUMIFS(Annualized_Investments!I$2:I$9991,Annualized_Investments!$B$2:$B$9991,$A34) -> 0 | J34: =SUMIFS(Annualized_Investments!J$2:J$9991,Annualized_Investments!$B$2:$B$9991,$A34) -> 0 | ... AG34: =SUMIFS(Annualized_Investments!AG$2:AG$9991,Annualized_Investments!$B$2:$B$9991,$A34) -> 0
A35: PHL_POW_PP_NU | C35: =SUMIFS(Annualized_Investments!C$2:C$9991,Annualized_Investments!$B$2:$B$9991,$A35) -> 0 | D35: =SUMIFS(Annualized_Investments!D$2:D$9991,Annualized_Investments!$B$2:$B$9991,$A35) -> 0 | E35: =SUMIFS(Annualized_Investments!E$2:E$9991,Annualized_Investments!$B$2:$B$9991,$A35) -> 0 | F35: =SUMIFS(Annualized_Investments!F$2:F$9991,Annualized_Investments!$B$2:$B$9991,$A35) -> 0 | G35: =SUMIFS(Annualized_Investments!G$2:G$9991,Annualized_Investments!$B$2:$B$9991,$A35) -> 0 | H35: =SUMIFS(Annualized_Investments!H$2:H$9991,Annualized_Investments!$B$2:$B$9991,$A35) -> 0 | I35: =SUMIFS(Annualized_Investments!I$2:I$9991,Annualized_Investments!$B$2:$B$9991,$A35) -> 0 | J35: =SUMIFS(Annualized_Investments!J$2:J$9991,Annualized_Investments!$B$2:$B$9991,$A35) -> 0 | ... AG35: =SUMIFS(Annualized_Investments!AG$2:AG$9991,Annualized_Investments!$B$2:$B$9991,$A35) -> 0
A36: PHL_POW_PP_NUSMR | C36: =SUMIFS(Annualized_Investments!C$2:C$9991,Annualized_Investments!$B$2:$B$9991,$A36) -> 0 | D36: =SUMIFS(Annualized_Investments!D$2:D$9991,Annualized_Investments!$B$2:$B$9991,$A36) -> 0 | E36: =SUMIFS(Annualized_Investments!E$2:E$9991,Annualized_Investments!$B$2:$B$9991,$A36) -> 0 | F36: =SUMIFS(Annualized_Investments!F$2:F$9991,Annualized_Investments!$B$2:$B$9991,$A36) -> 0 | G36: =SUMIFS(Annualized_Investments!G$2:G$9991,Annualized_Investments!$B$2:$B$9991,$A36) -> 0 | H36: =SUMIFS(Annualized_Investments!H$2:H$9991,Annualized_Investments!$B$2:$B$9991,$A36) -> 0 | I36: =SUMIFS(Annualized_Investments!I$2:I$9991,Annualized_Investments!$B$2:$B$9991,$A36) -> 0 | J36: =SUMIFS(Annualized_Investments!J$2:J$9991,Annualized_Investments!$B$2:$B$9991,$A36) -> 0 | ... AG36: =SUMIFS(Annualized_Investments!AG$2:AG$9991,Annualized_Investments!$B$2:$B$9991,$A36) -> 4259.8242
... A42: PHL_POW_TD | C42: =SUMIFS(Annualized_Investments!C$2:C$9991,Annualized_Investments!$B$2:$B$9991,$A42) -> 0 | D42: =SUMIFS(Annualized_Investments!D$2:D$9991,Annualized_Investments!$B$2:$B$9991,$A42) -> 0 | E42: =SUMIFS(Annualized_Investments!E$2:E$9991,Annualized_Investments!$B$2:$B$9991,$A42) -> 0 | F42: =SUMIFS(Annualized_Investments!F$2:F$9991,Annualized_Investments!$B$2:$B$9991,$A42) -> 0 | G42: =SUMIFS(Annualized_Investments!G$2:G$9991,Annualized_Investments!$B$2:$B$9991,$A42) -> 0 | H42: =SUMIFS(Annualized_Investments!H$2:H$9991,Annualized_Investments!$B$2:$B$9991,$A42) -> 23.98163 | I42: =SUMIFS(Annualized_Investments!I$2:I$9991,Annualized_Investments!$B$2:$B$9991,$A42) -> 92.675423 | J42: =SUMIFS(Annualized_Investments!J$2:J$9991,Annualized_Investments!$B$2:$B$9991,$A42) -> 161.36922 | ... AG42: =SUMIFS(Annualized_Investments!AG$2:AG$9991,Annualized_Investments!$B$2:$B$9991,$A42) -> 2425.5664
A43: Total Annualized Investments (Million USD) | C43: =SUM(C25:C42) -> 234.83856 | D43: =SUM(D25:D42) -> 756.46065 | E43: =SUM(E25:E42) -> 918.84101 | F43: =SUM(F25:F42) -> 1006.569 | G43: =SUM(G25:G42) -> 1158.3122 | H43: =SUM(H25:H42) -> 1276.2681 | I43: =SUM(I25:I42) -> 1551.5727 | J43: =SUM(J25:J42) -> 1840.1869 | ... AG43: =SUM(AG25:AG42) -> 11615.939

Sheet Emissions PEP
A1: PEP Scenario
A2: Annual Technology Emission by Mode (Mton)
A3: Emission / Technology | B3: 2020 | C3: 2021 | D3: 2022 | E3: 2023 | F3: 2024 | G3: 2025 | H3: 2026 | I3: 2027 | J3: 2028 | K3: 2029 | L3: 2030 | M3: 2031 | N3: 2032 | O3: 2033 | P3: 2034 | Q3: 2035 | R3: 2036 | S3: 2037 | T3: 2038 | U3: 2039 | V3: 2040 | W3: 2041 | X3: 2042 | Y3: 2043 | Z3: 2044 | AA3: 2045 | AB3: 2046 | AC3: 2047 | AD3: 2048 | AE3: 2049 | AF3: 2050 | AG3: 2051 | AH3: 2052 | AI3: 2053
A4: CO2e | B4: 97.2368 | C4: 130.9558 | D4: 138.0291 | E4: 144.6563 | F4: 152.1883 | G4: 152.9749 | H4: 150.9351 | I4: 156.3485 | J4: 161.7406 | K4: 167.065 | L4: 160.7758 | M4: 170.8505 | N4: 180.1604 | O4: 190.0282 | P4: 184.3807 | Q4: 177.0234 | R4: 170.2539 | S4: 162.4349 | T4: 151.9248 | U4: 147.3548 | V4: 144.5833 | W4: 147.1184 | X4: 149.751 | Y4: 153.1202 | Z4: 155.7341 | AA4: 157.4759 | AB4: 154.8883 | AC4: 150.5416 | AD4: 149.9719 | AE4: 149.2755 | AF4: 145.2971 | AG4: 145.6345 | AH4: 144.8147 | AI4: 143.3112
A5: PHL_POW_BH2_NG | B5: 0 | C5: 0 | D5: 0 | E5: 0 | F5: 0 | G5: 0 | H5: 0 | I5: 0 | J5: 0 | K5: 0 | L5: 0 | M5: 0 | N5: 0 | O5: 0 | P5: 0 | Q5: 0 | R5: 0 | S5: 0 | T5: 0 | U5: 0 | V5: 0 | W5: 0 | X5: 0 | Y5: 0 | Z5: 0 | AA5: 0 | AB5: 0 | AC5: 0 | AD5: 0 | AE5: 0 | AF5: 0 | AG5: 0 | AH5: 0 | AI5: 0
A6: PHL_POW_DAC | B6: 0 | C6: 0 | D6: 0 | E6: 0 | F6: 0 | G6: 0 | H6: 0 | I6: 0 | J6: 0 | K6: 0 | L6: 0 | M6: 0 | N6: 0 | O6: 0 | P6: 0 | Q6: 0 | R6: 0 | S6: 0 | T6: 0 | U6: 0 | V6: 0 | W6: 0 | X6: 0 | Y6: 0 | Z6: 0 | AA6: 0 | AB6: 0 | AC6: 0 | AD6: 0 | AE6: 0 | AF6: 0 | AG6: 0 | AH6: 0 | AI6: 0
A7: PHL_POW_PP_BIOM_CCS | B7: 0 | C7: 0 | D7: 0 | E7: 0 | F7: 0 | G7: 0 | H7: 0 | I7: 0 | J7: 0 | K7: 0 | L7: 0 | M7: 0 | N7: 0 | O7: 0 | P7: 0 | Q7: 0 | R7: 0 | S7: 0 | T7: 0 | U7: 0 | V7: 0 | W7: 0 | X7: 0 | Y7: 0 | Z7: 0 | AA7: 0 | AB7: 0 | AC7: 0 | AD7: 0 | AE7: 0 | AF7: 0 | AG7: 0 | AH7: 0 | AI7: 0
A8: PHL_POW_PP_COAL_CCS | B8: 0 | C8: 0 | D8: 0 | E8: 0 | F8: 0 | G8: 0 | H8: 0 | I8: 0 | J8: 0 | K8: 0 | L8: 0 | M8: 0 | N8: 0 | O8: 0 | P8: 0 | Q8: 0 | R8: 0 | S8: 0 | T8: 0 | U8: 0 | V8: 0 | W8: 0 | X8: 0 | Y8: 0 | Z8: 0 | AA8: 0 | AB8: 0 | AC8: 0 | AD8: 0 | AE8: 0 | AF8: 0 | AG8: 0 | AH8: 0 | AI8: 0
A9: PHL_POW_PP_NGCC_CCS | B9: 0 | C9: 0 | D9: 0 | E9: 0 | F9: 0 | G9: 0 | H9: 0 | I9: 0 | J9: 0 | K9: 0 | L9: 0 | M9: 0 | N9: 0 | O9: 0 | P9: 0 | Q9: 0 | R9: 0 | S9: 0 | T9: 0 | U9: 0 | V9: 0 | W9: 0 | X9: 0 | Y9: 0 | Z9: 0 | AA9: 0 | AB9: 0 | AC9: 0 | AD9: 0 | AE9: 0 | AF9: 0 | AG9: 0 | AH9: 0 | AI9: 0
A10: PHL_PRO_PROC_COAL | B10: 70.5467 | C10: 110.0799 | D10: 118.0273 | E10: 126.249 | F10: 133.6535 | G10: 141.6708 | H10: 140.1513 | I10: 145.8409 | J10: 151.4712 | K10: 156.888 | L10: 150.7372 | M10: 160.7468 | N10: 170.4105 | O10: 181.073 | P10: 175.5778 | Q10: 168.3504 | R10: 158.6633 | S10: 150.888 | T10: 140.8871 | U10: 134.7674 | V10: 130.1214 | W10: 131.69 | X10: 133.3073 | Y10: 135.2845 | Z10: 136.8941 | AA10: 137.9203 | AB10: 134.6741 | AC10: 129.9811 | AD10: 129.1131 | AE10: 128.0754 | AF10: 123.0745 | AG10: 122.9684 | AH10: 121.2248 | AI10: 114.9555
A11: PHL_PRO_PROC_NG | B11: 7.3094 | C11: 8.0315 | D11: 8.0246 | E11: 7.3979 | F11: 8.4052 | G11: 2.1297 | H11: 2.5266 | I11: 2.4565 | J11: 2.282 | K11: 2.8785 | L11: 2.9381 | M11: 3.0524 | N11: 4.4241 | O11: 7.1202 | P11: 7.8858 | Q11: 8.673 | R11: 11.5906 | S11: 11.5469 | T11: 11.0377 | U11: 12.5874 | V11: 14.4619 | W11: 15.4284 | X11: 16.4437 | Y11: 17.8357 | Z11: 18.84 | AA11: 19.5556 | AB11: 20.2142 | AC11: 20.5605 | AD11: 20.8588 | AE11: 21.2001 | AF11: 22.2226 | AG11: 22.6661 | AH11: 23.5899 | AI11: 28.3557
A12: PHL_PRO_PROC_OIL | B12: 19.3807 | C12: 12.8444 | D12: 11.9772 | E12: 11.0094 | F12: 10.1296 | G12: 9.1744 | H12: 8.2572 | I12: 8.0511 | J12: 7.9874 | K12: 7.2985 | L12: 7.1005 | M12: 7.0513 | N12: 5.3258 | O12: 1.835 | P12: 0.9171 | Q12: 0 | R12: 0 | S12: 0 | T12: 0 | U12: 0 | V12: 0 | W12: 0 | X12: 0 | Y12: 0 | Z12: 0 | AA12: 0 | AB12: 0 | AC12: 0 | AD12: 0 | AE12: 0 | AF12: 0 | AG12: 0 | AH12: 0 | AI12: 0
A13: PM2_5 | B13: 64.8365 | C13: 67.0945 | D13: 69.3282 | E13: 71.561 | F13: 73.7941 | G13: 76.0273 | H13: 76.4112 | I13: 76.7932 | J13: 77.1773 | K13: 77.559 | L13: 77.9407 | M13: 78.6987 | N13: 79.4568 | O13: 80.2152 | P13: 80.9736 | Q13: 81.7317 | R13: 82.998 | S13: 84.263 | T13: 85.53 | U13: 86.7957 | V13: 88.063 | W13: 91.4029 | X13: 94.7412 | Y13: 98.0808 | Z13: 101.4212 | AA13: 104.7608 | AB13: 108.384 | AC13: 112.0074 | AD13: 115.633 | AE13: 119.2571 | AF13: 123.2576 | AG13: 127.2112 | AH13: 131.2236 | AI13: 136.0443
A14: PHL_HOU_COOK_BIOM | B14: 0.0026 | C14: 0 | D14: 0 | E14: 0 | F14: 0 | G14: 0 | H14: 0 | I14: 0 | J14: 0 | K14: 0 | L14: 0 | M14: 0 | N14: 0 | O14: 0 | P14: 0 | Q14: 0 | R14: 0 | S14: 0 | T14: 0 | U14: 0 | V14: 0 | W14: 0 | X14: 0 | Y14: 0 | Z14: 0 | AA14: 0 | AB14: 0 | AC14: 0 | AD14: 0 | AE14: 0 | AF14: 0 | AG14: 0 | AH14: 0 | AI14: 0
... A30: PHL_TRA_VAN_LIQ | B30: 5.773 | C30: 6.1101 | D30: 6.4472 | E30: 6.7844 | F30: 7.1215 | G30: 7.4586 | H30: 7.874 | I30: 8.2886 | J30: 8.704 | K30: 9.1186 | L30: 9.5333 | M30: 10.0308 | N30: 10.5276 | O30: 11.0252 | P30: 11.5227 | Q30: 12.0195 | R30: 12.6271 | S30: 13.2339 | T30: 13.8415 | U30: 14.4483 | V30: 15.0559 | W30: 15.7627 | X30: 16.4695 | Y30: 17.1763 | Z30: 17.8839 | AA30: 18.5907 | AB30: 19.3603 | AC30: 20.1298 | AD30: 20.9002 | AE30: 21.6698 | AF30: 22.4394 | AG30: 23.2174 | AH30: 23.9948 | AI30: 24.7721

Sheet Cost_of_ELCgen
A1: Philippines
A3: AnnualFixedOperatingCost + AnnualVariableOperating Cost (Million USD) | C3: 2020 | D3: 2021 | E3: 2022 | F3: 2023 | G3: 2024 | H3: 2025 | I3: 2026 | J3: 2027 | K3: 2028 | L3: 2029 | M3: 2030 | N3: 2031 | O3: 2032 | P3: 2033 | Q3: 2034 | R3: 2035 | S3: 2036 | T3: 2037 | U3: 2038 | V3: 2039 | W3: 2040 | X3: 2041 | Y3: 2042 | Z3: 2043 | AA3: 2044 | AB3: 2045 | AC3: 2046 | AD3: 2047 | AE3: 2048 | AF3: 2049 | AG3: 2050
A4: TOTAL (Fixed & Variable) | C4: =SUM(C6:C9)+SUM(C38:C54) -> 10162.893 | D4: =SUM(D6:D9)+SUM(D38:D54) -> 6155.3583 | E4: =SUM(E6:E9)+SUM(E38:E54) -> 6401.8118 | F4: =SUM(F6:F9)+SUM(F38:F54) -> 6582.7586 | G4: =SUM(G6:G9)+SUM(G38:G54) -> 6991.1589 | H4: =SUM(H6:H9)+SUM(H38:H54) -> 5841.0003 | I4: =SUM(I6:I9)+SUM(I38:I54) -> 5978.6581 | J4: =SUM(J6:J9)+SUM(J38:J54) -> 6331.6685 | ... AG4: =SUM(AG6:AG9)+SUM(AG38:AG54) -> 10572.196
A5: VARIABLE
A6: PHL_PRO_EXTR_NG | C6: =SUMIFS(Variable!C$2:C$9992,Variable!$B$2:$B$9992,$A6) -> 1261.3245 | D6: =SUMIFS(Variable!D$2:D$9992,Variable!$B$2:$B$9992,$A6) -> 1391.3286 | E6: =SUMIFS(Variable!E$2:E$9992,Variable!$B$2:$B$9992,$A6) -> 1395.6857 | F6: =SUMIFS(Variable!F$2:F$9992,Variable!$B$2:$B$9992,$A6) -> 1291.8042 | G6: =SUMIFS(Variable!G$2:G$9992,Variable!$B$2:$B$9992,$A6) -> 1473.504 | H6: =SUMIFS(Variable!H$2:H$9992,Variable!$B$2:$B$9992,$A6) -> 374.8344 | I6: =SUMIFS(Variable!I$2:I$9992,Variable!$B$2:$B$9992,$A6) -> 446.4331 | J6: =SUMIFS(Variable!J$2:J$9992,Variable!$B$2:$B$9992,$A6) -> 435.7027 | ... AG6: =SUMIFS(Variable!AG$2:AG$9992,Variable!$B$2:$B$9992,$A6) -> 4130.2355
A7: PHL_PRO_EXTR_OIL | C7: =SUMIFS(Variable!C$2:C$9992,Variable!$B$2:$B$9992,$A7) -> 955.7753 | D7: =SUMIFS(Variable!D$2:D$9992,Variable!$B$2:$B$9992,$A7) -> 0 | E7: =SUMIFS(Variable!E$2:E$9992,Variable!$B$2:$B$9992,$A7) -> 8.9153 | F7: =SUMIFS(Variable!F$2:F$9992,Variable!$B$2:$B$9992,$A7) -> 0 | G7: =SUMIFS(Variable!G$2:G$9992,Variable!$B$2:$B$9992,$A7) -> 6.9055 | H7: =SUMIFS(Variable!H$2:H$9992,Variable!$B$2:$B$9992,$A7) -> 0 | I7: =SUMIFS(Variable!I$2:I$9992,Variable!$B$2:$B$9992,$A7) -> 0 | J7: =SUMIFS(Variable!J$2:J$9992,Variable!$B$2:$B$9992,$A7) -> 135.264 | ... AG7: =SUMIFS(Variable!AG$2:AG$9992,Variable!$B$2:$B$9992,$A7) -> 0
A8: PHL_PRO_EXTR_COAL | C8: =SUMIFS(Variable!C$2:C$9992,Variable!$B$2:$B$9992,$A8) -> 2023.5934 | D8: =SUMIFS(Variable!D$2:D$9992,Variable!$B$2:$B$9992,$A8) -> 3168.6587 | E8: =SUMIFS(Variable!E$2:E$9992,Variable!$B$2:$B$9992,$A8) -> 3409.305 | F8: =SUMIFS(Variable!F$2:F$9992,Variable!$B$2:$B$9992,$A8) -> 3659.5005 | G8: =SUMIFS(Variable!G$2:G$9992,Variable!$B$2:$B$9992,$A8) -> 3887.5842 | H8: =SUMIFS(Variable!H$2:H$9992,Variable!$B$2:$B$9992,$A8) -> 4135.0404 | I8: =SUMIFS(Variable!I$2:I$9992,Variable!$B$2:$B$9992,$A8) -> 4104.7955 | J8: =SUMIFS(Variable!J$2:J$9992,Variable!$B$2:$B$9992,$A8) -> 4286.1149 | ... AG8: =SUMIFS(Variable!AG$2:AG$9992,Variable!$B$2:$B$9992,$A8) -> 0
A9: PHL_PRO_PROC_BIOM | C9: =SUMIFS(Variable!C$2:C$9992,Variable!$B$2:$B$9992,$A9) -> 4868.8589 | D9: =SUMIFS(Variable!D$2:D$9992,Variable!$B$2:$B$9992,$A9) -> 399.9788 | E9: =SUMIFS(Variable!E$2:E$9992,Variable!$B$2:$B$9992,$A9) -> 344.0609 | F9: =SUMIFS(Variable!F$2:F$9992,Variable!$B$2:$B$9992,$A9) -> 387.3222 | G9: =SUMIFS(Variable!G$2:G$9992,Variable!$B$2:$B$9992,$A9) -> 364.6882 | H9: =SUMIFS(Variable!H$2:H$9992,Variable!$B$2:$B$9992,$A9) -> 47.7259 | I9: =SUMIFS(Variable!I$2:I$9992,Variable!$B$2:$B$9992,$A9) -> 48.1232 | J9: =SUMIFS(Variable!J$2:J$9992,Variable!$B$2:$B$9992,$A9) -> 29.5016 | ... AG9: =SUMIFS(Variable!AG$2:AG$9992,Variable!$B$2:$B$9992,$A9) -> 0
A10: PHL_POW_CHP_BIOM_OLD | C10: =SUMIFS(Variable!C$2:C$9992,Variable!$B$2:$B$9992,$A10) -> 0.0004 | D10: =SUMIFS(Variable!D$2:D$9992,Variable!$B$2:$B$9992,$A10) -> 0.0005 | E10: =SUMIFS(Variable!E$2:E$9992,Variable!$B$2:$B$9992,$A10) -> 0.0005 | F10: =SUMIFS(Variable!F$2:F$9992,Variable!$B$2:$B$9992,$A10) -> 0.0005 | G10: =SUMIFS(Variable!G$2:G$9992,Variable!$B$2:$B$9992,$A10) -> 0.0005 | H10: =SUMIFS(Variable!H$2:H$9992,Variable!$B$2:$B$9992,$A10) -> 0 | I10: =SUMIFS(Variable!I$2:I$9992,Variable!$B$2:$B$9992,$A10) -> 0 | J10: =SUMIFS(Variable!J$2:J$9992,Variable!$B$2:$B$9992,$A10) -> 0 | ... AG10: =SUMIFS(Variable!AG$2:AG$9992,Variable!$B$2:$B$9992,$A10) -> 0
A11: PHL_POW_CHP_COAL_OLD | C11: =SUMIFS(Variable!C$2:C$9992,Variable!$B$2:$B$9992,$A11) -> 0.0209 | D11: =SUMIFS(Variable!D$2:D$9992,Variable!$B$2:$B$9992,$A11) -> 0.0223 | E11: =SUMIFS(Variable!E$2:E$9992,Variable!$B$2:$B$9992,$A11) -> 0.0239 | F11: =SUMIFS(Variable!F$2:F$9992,Variable!$B$2:$B$9992,$A11) -> 0.0266 | G11: =SUMIFS(Variable!G$2:G$9992,Variable!$B$2:$B$9992,$A11) -> 0.0286 | H11: =SUMIFS(Variable!H$2:H$9992,Variable!$B$2:$B$9992,$A11) -> 0.0262 | I11: =SUMIFS(Variable!I$2:I$9992,Variable!$B$2:$B$9992,$A11) -> 0.025 | J11: =SUMIFS(Variable!J$2:J$9992,Variable!$B$2:$B$9992,$A11) -> 0.0232 | ... AG11: =SUMIFS(Variable!AG$2:AG$9992,Variable!$B$2:$B$9992,$A11) -> 0
A12: PHL_POW_GEO_OLD | C12: =SUMIFS(Variable!C$2:C$9992,Variable!$B$2:$B$9992,$A12) -> 0.0039 | D12: =SUMIFS(Variable!D$2:D$9992,Variable!$B$2:$B$9992,$A12) -> 0.0036 | E12: =SUMIFS(Variable!E$2:E$9992,Variable!$B$2:$B$9992,$A12) -> 0.0038 | F12: =SUMIFS(Variable!F$2:F$9992,Variable!$B$2:$B$9992,$A12) -> 0.0039 | G12: =SUMIFS(Variable!G$2:G$9992,Variable!$B$2:$B$9992,$A12) -> 0.0039 | H12: =SUMIFS(Variable!H$2:H$9992,Variable!$B$2:$B$9992,$A12) -> 0.004 | I12: =SUMIFS(Variable!I$2:I$9992,Variable!$B$2:$B$9992,$A12) -> 0.0067 | J12: =SUMIFS(Variable!J$2:J$9992,Variable!$B$2:$B$9992,$A12) -> 0.0067 | ... AG12: =SUMIFS(Variable!AG$2:AG$9992,Variable!$B$2:$B$9992,$A12) -> 0.0097
A13: PHL_POW_PP_BIOM_CCS | C13: =SUMIFS(Variable!C$2:C$9992,Variable!$B$2:$B$9992,$A13) -> 0 | D13: =SUMIFS(Variable!D$2:D$9992,Variable!$B$2:$B$9992,$A13) -> 0 | E13: =SUMIFS(Variable!E$2:E$9992,Variable!$B$2:$B$9992,$A13) -> 0 | F13: =SUMIFS(Variable!F$2:F$9992,Variable!$B$2:$B$9992,$A13) -> 0 | G13: =SUMIFS(Variable!G$2:G$9992,Variable!$B$2:$B$9992,$A13) -> 0 | H13: =SUMIFS(Variable!H$2:H$9992,Variable!$B$2:$B$9992,$A13) -> 0 | I13: =SUMIFS(Variable!I$2:I$9992,Variable!$B$2:$B$9992,$A13) -> 0 | J13: =SUMIFS(Variable!J$2:J$9992,Variable!$B$2:$B$9992,$A13) -> 0 | ... AG13: =SUMIFS(Variable!AG$2:AG$9992,Variable!$B$2:$B$9992,$A13) -> 0
A14: PHL_POW_PP_COAL | C14: =SUMIFS(Variable!C$2:C$9992,Variable!$B$2:$B$9992,$A14) -> 0 | D14: =SUMIFS(Variable!D$2:D$9992,Variable!$B$2:$B$9992,$A14) -> 0 | E14: =SUMIFS(Variable!E$2:E$9992,Variable!$B$2:$B$9992,$A14) -> 0 | F14: =SUMIFS(Variable!F$2:F$9992,Variable!$B$2:$B$9992,$A14) -> 0 | G14: =SUMIFS(Variable!G$2:G$9992,Variable!$B$2:$B$9992,$A14) -> 0 | H14: =SUMIFS(Variable!H$2:H$9992,Variable!$B$2:$B$9992,$A14) -> 0.0066 | I14: =SUMIFS(Variable!I$2:I$9992,Variable!$B$2:$B$9992,$A14) -> 0.0066 | J14: =SUMIFS(Variable!J$2:J$9992,Variable!$B$2:$B$9992,$A14) -> 0.0113 | ... AG14: =SUMIFS(Variable!AG$2:AG$9992,Variable!$B$2:$B$9992,$A14) -> 0.0223
A15: PHL_POW_PP_COAL_CCS | C15: =SUMIFS(Variable!C$2:C$9992,Variable!$B$2:$B$9992,$A15) -> 0 | D15: =SUMIFS(Variable!D$2:D$9992,Variable!$B$2:$B$9992,$A15) -> 0 | E15: =SUMIFS(Variable!E$2:E$9992,Variable!$B$2:$B$9992,$A15) -> 0 | F15: =SUMIFS(Variable!F$2:F$9992,Variable!$B$2:$B$9992,$A15) -> 0 | G15: =SUMIFS(Variable!G$2:G$9992,Variable!$B$2:$B$9992,$A15) -> 0 | H15: =SUMIFS(Variable!H$2:H$9992,Variable!$B$2:$B$9992,$A15) -> 0 | I15: =SUMIFS(Variable!I$2:I$9992,Variable!$B$2:$B$9992,$A15) -> 0 | J15: =SUMIFS(Variable!J$2:J$9992,Variable!$B$2:$B$9992,$A15) -> 0 | ... AG15: =SUMIFS(Variable!AG$2:AG$9992,Variable!$B$2:$B$9992,$A15) -> 0
A16: PHL_POW_PP_H2 | C16: =SUMIFS(Variable!C$2:C$9992,Variable!$B$2:$B$9992,$A16) -> 0 | D16: =SUMIFS(Variable!D$2:D$9992,Variable!$B$2:$B$9992,$A16) -> 0 | E16: =SUMIFS(Variable!E$2:E$9992,Variable!$B$2:$B$9992,$A16) -> 0 | F16: =SUMIFS(Variable!F$2:F$9992,Variable!$B$2:$B$9992,$A16) -> 0 | G16: =SUMIFS(Variable!G$2:G$9992,Variable!$B$2:$B$9992,$A16) -> 0 | H16: =SUMIFS(Variable!H$2:H$9992,Variable!$B$2:$B$9992,$A16) -> 0 | I16: =SUMIFS(Variable!I$2:I$9992,Variable!$B$2:$B$9992,$A16) -> 0 | J16: =SUMIFS(Variable!J$2:J$9992,Variable!$B$2:$B$9992,$A16) -> 0 | ... AG16: =SUMIFS(Variable!AG$2:AG$9992,Variable!$B$2:$B$9992,$A16) -> 0
A17: PHL_POW_PP_HY_LA | C17: =SUMIFS(Variable!C$2:C$9992,Variable!$B$2:$B$9992,$A17) -> 0.0026 | D17: =SUMIFS(Variable!D$2:D$9992,Variable!$B$2:$B$9992,$A17) -> 0.0033 | E17: =SUMIFS(Variable!E$2:E$9992,Variable!$B$2:$B$9992,$A17) -> 0.0036 | F17: =SUMIFS(Variable!F$2:F$9992,Variable!$B$2:$B$9992,$A17) -> 0.0037 | G17: =SUMIFS(Variable!G$2:G$9992,Variable!$B$2:$B$9992,$A17) -> 0.0039 | H17: =SUMIFS(Variable!H$2:H$9992,Variable!$B$2:$B$9992,$A17) -> 0.0039 | I17: =SUMIFS(Variable!I$2:I$9992,Variable!$B$2:$B$9992,$A17) -> 0.0039 | J17: =SUMIFS(Variable!J$2:J$9992,Variable!$B$2:$B$9992,$A17) -> 0.0039 | ... AG17: =SUMIFS(Variable!AG$2:AG$9992,Variable!$B$2:$B$9992,$A17) -> 0.0032
... A27: PHL_POW_TD | C27: =SUMIFS(Variable!C$2:C$9992,Variable!$B$2:$B$9992,$A27) -> 0.03 | D27: =SUMIFS(Variable!D$2:D$9992,Variable!$B$2:$B$9992,$A27) -> 0.03 | E27: =SUMIFS(Variable!E$2:E$9992,Variable!$B$2:$B$9992,$A27) -> 0.0315 | F27: =SUMIFS(Variable!F$2:F$9992,Variable!$B$2:$B$9992,$A27) -> 0.033 | G27: =SUMIFS(Variable!G$2:G$9992,Variable!$B$2:$B$9992,$A27) -> 0.0345 | H27: =SUMIFS(Variable!H$2:H$9992,Variable!$B$2:$B$9992,$A27) -> 0.0357 | I27: =SUMIFS(Variable!I$2:I$9992,Variable!$B$2:$B$9992,$A27) -> 0.0369 | J27: =SUMIFS(Variable!J$2:J$9992,Variable!$B$2:$B$9992,$A27) -> 0.039 | ... AG27: =SUMIFS(Variable!AG$2:AG$9992,Variable!$B$2:$B$9992,$A27) -> 0.1038
A29: Only grid-connected
A30: Coal | C30: =SUM(C225,C228:C229)*C120 -> 1994.5146 | D30: =SUM(D225,D228:D229)*D120 -> 2135.6259 | E30: =SUM(E225,E228:E229)*E120 -> 2295.2716 | F30: =SUM(F225,F228:F229)*F120 -> 2558.2788 | G30: =SUM(G225,G228:G229)*G120 -> 2763.4075 | H30: =SUM(H225,H228:H229)*H120 -> 3013.7481 | I30: =SUM(I225,I228:I229)*I120 -> 2905.3081 | J30: =SUM(J225,J228:J229)*J120 -> 3073.9003 | ... AG30: =SUM(AG225,AG228:AG229)*AG120 -> 1836.0367
A31: Natural gas | C31: =SUM(C232:C233)*C122 -> 0 | D31: =SUM(D232:D233)*D122 -> 0 | E31: =SUM(E232:E233)*E122 -> 0 | F31: =SUM(F232:F233)*F122 -> 0 | G31: =SUM(G232:G233)*G122 -> 0 | H31: =SUM(H232:H233)*H122 -> 93.032588 | I31: =SUM(I232:I233)*I122 -> 101.02545 | J31: =SUM(J232:J233)*J122 -> 68.000747 | ... AG31: =SUM(AG232:AG233)*AG122 -> 1440.4149
A32: Oil | C32: =C239*C121 -> 647.30077 | D32: =D239*D121 -> 430.62557 | E32: =E239*E121 -> 682.24145 | F32: =F239*F121 -> 358.8861 | G32: =G239*G121 -> 375.2526 | H32: =H239*H121 -> 0 | I32: =I239*I121 -> 0 | J32: =J239*J121 -> 0 | ... AG32: =AG239*AG121 -> 0
A33: Biomass | C33: =SUM(C224,C227)*C123 -> 288.048 | D33: =SUM(D224,D227)*D123 -> 332.9808 | E33: =SUM(E224,E227)*E123 -> 304.6272 | F33: =SUM(F224,F227)*F123 -> 324.6608 | G33: =SUM(G224,G227)*G123 -> 333.2384 | H33: =SUM(H224,H227)*H123 -> 0 | I33: =SUM(I224,I227)*I123 -> 0 | J33: =SUM(J224,J227)*J123 -> 0 | ... AG33: =SUM(AG224,AG227)*AG123 -> 0
A34: Uranium | C34: =C241*C124 -> 0 | D34: =D241*D124 -> 0 | E34: =E241*E124 -> 0 | F34: =F241*F124 -> 0 | G34: =G241*G124 -> 0 | H34: =H241*H124 -> 0 | I34: =I241*I124 -> 0 | J34: =J241*J124 -> 0 | ... AG34: =AG241*AG124 -> 1157.177
A35: TOTAL (Fixed & Variable) | C35: =SUM(C38:C55)+SUM(C30:C34)+SUM(C10:C27) -> 3983.2703 | D35: =SUM(D38:D55)+SUM(D30:D34)+SUM(D10:D27) -> 4094.6927 | E35: =SUM(E38:E55)+SUM(E30:E34)+SUM(E10:E27) -> 4526.0569 | F35: =SUM(F38:F55)+SUM(F30:F34)+SUM(F10:F27) -> 4486.033 | G35: =SUM(G38:G55)+SUM(G30:G34)+SUM(G10:G27) -> 4730.4557 | H35: =SUM(H38:H55)+SUM(H30:H34)+SUM(H10:H27) -> 4390.2596 | I35: =SUM(I38:I55)+SUM(I30:I34)+SUM(I10:I27) -> 4385.722 | J35: =SUM(J38:J55)+SUM(J30:J34)+SUM(J10:J27) -> 4587.073 | ... AG35: =SUM(AG38:AG55)+SUM(AG30:AG34)+SUM(AG10:AG27) -> 10875.82
A37: FIXED | C37: 2020 | D37: 2021 | E37: 2022 | F37: 2023 | G37: 2024 | H37: 2025 | I37: 2026 | J37: 2027 | K37: 2028 | L37: 2029 | M37: 2030 | N37: 2031 | O37: 2032 | P37: 2033 | Q37: 2034 | R37: 2035 | S37: 2036 | T37: 2037 | U37: 2038 | V37: 2039 | W37: 2040 | X37: 2041 | Y37: 2042 | Z37: 2043 | AA37: 2044 | AB37: 2045 | AC37: 2046 | AD37: 2047 | AE37: 2048 | AF37: 2049 | AG37: 2050
A38: PHL_POW_CHP_BIOM_OLD | C38: =SUMIFS(Fixed!C$2:C$10000,Fixed!$B$2:$B$10000,$A38) -> 44.748 | D38: =SUMIFS(Fixed!D$2:D$10000,Fixed!$B$2:$B$10000,$A38) -> 44.748 | E38: =SUMIFS(Fixed!E$2:E$10000,Fixed!$B$2:$B$10000,$A38) -> 52.128 | F38: =SUMIFS(Fixed!F$2:F$10000,Fixed!$B$2:$B$10000,$A38) -> 52.668 | G38: =SUMIFS(Fixed!G$2:G$10000,Fixed!$B$2:$B$10000,$A38) -> 53.559 | H38: =SUMIFS(Fixed!H$2:H$10000,Fixed!$B$2:$B$10000,$A38) -> 53.559 | I38: =SUMIFS(Fixed!I$2:I$10000,Fixed!$B$2:$B$10000,$A38) -> 53.559 | J38: =SUMIFS(Fixed!J$2:J$10000,Fixed!$B$2:$B$10000,$A38) -> 53.559 | ... AG38: =SUMIFS(Fixed!AG$2:AG$10000,Fixed!$B$2:$B$10000,$A38) -> 45.693
A39: PHL_POW_CHP_COAL_OLD | C39: =SUMIFS(Fixed!C$2:C$10000,Fixed!$B$2:$B$10000,$A39) -> 491.0355 | D39: =SUMIFS(Fixed!D$2:D$10000,Fixed!$B$2:$B$10000,$A39) -> 491.0355 | E39: =SUMIFS(Fixed!E$2:E$10000,Fixed!$B$2:$B$10000,$A39) -> 491.0355 | F39: =SUMIFS(Fixed!F$2:F$10000,Fixed!$B$2:$B$10000,$A39) -> 491.0355 | G39: =SUMIFS(Fixed!G$2:G$10000,Fixed!$B$2:$B$10000,$A39) -> 464.0355 | H39: =SUMIFS(Fixed!H$2:H$10000,Fixed!$B$2:$B$10000,$A39) -> 464.0355 | I39: =SUMIFS(Fixed!I$2:I$10000,Fixed!$B$2:$B$10000,$A39) -> 464.0355 | J39: =SUMIFS(Fixed!J$2:J$10000,Fixed!$B$2:$B$10000,$A39) -> 464.0355 | ... AG39: =SUMIFS(Fixed!AG$2:AG$10000,Fixed!$B$2:$B$10000,$A39) -> 286.461
A40: PHL_POW_GEO_OLD | C40: =SUMIFS(Fixed!C$2:C$10000,Fixed!$B$2:$B$10000,$A40) -> 144.394 | D40: =SUMIFS(Fixed!D$2:D$10000,Fixed!$B$2:$B$10000,$A40) -> 144.394 | E40: =SUMIFS(Fixed!E$2:E$10000,Fixed!$B$2:$B$10000,$A40) -> 144.8195 | F40: =SUMIFS(Fixed!F$2:F$10000,Fixed!$B$2:$B$10000,$A40) -> 140.8618 | G40: =SUMIFS(Fixed!G$2:G$10000,Fixed!$B$2:$B$10000,$A40) -> 141.6349 | H40: =SUMIFS(Fixed!H$2:H$10000,Fixed!$B$2:$B$10000,$A40) -> 145.7404 | I40: =SUMIFS(Fixed!I$2:I$10000,Fixed!$B$2:$B$10000,$A40) -> 243.0334 | J40: =SUMIFS(Fixed!J$2:J$10000,Fixed!$B$2:$B$10000,$A40) -> 243.0334 | ... AG40: =SUMIFS(Fixed!AG$2:AG$10000,Fixed!$B$2:$B$10000,$A40) -> 459.4748
A41: PHL_POW_PP_BIOM_CCS | C41: =SUMIFS(Fixed!C$2:C$10000,Fixed!$B$2:$B$10000,$A41) -> 0 | D41: =SUMIFS(Fixed!D$2:D$10000,Fixed!$B$2:$B$10000,$A41) -> 0 | E41: =SUMIFS(Fixed!E$2:E$10000,Fixed!$B$2:$B$10000,$A41) -> 0 | F41: =SUMIFS(Fixed!F$2:F$10000,Fixed!$B$2:$B$10000,$A41) -> 0 | G41: =SUMIFS(Fixed!G$2:G$10000,Fixed!$B$2:$B$10000,$A41) -> 0 | H41: =SUMIFS(Fixed!H$2:H$10000,Fixed!$B$2:$B$10000,$A41) -> 0 | I41: =SUMIFS(Fixed!I$2:I$10000,Fixed!$B$2:$B$10000,$A41) -> 0 | J41: =SUMIFS(Fixed!J$2:J$10000,Fixed!$B$2:$B$10000,$A41) -> 0 | ... AG41: =SUMIFS(Fixed!AG$2:AG$10000,Fixed!$B$2:$B$10000,$A41) -> 0
A42: PHL_POW_PP_COAL | C42: =SUMIFS(Fixed!C$2:C$10000,Fixed!$B$2:$B$10000,$A42) -> 0 | D42: =SUMIFS(Fixed!D$2:D$10000,Fixed!$B$2:$B$10000,$A42) -> 32.877 | E42: =SUMIFS(Fixed!E$2:E$10000,Fixed!$B$2:$B$10000,$A42) -> 67.7675 | F42: =SUMIFS(Fixed!F$2:F$10000,Fixed!$B$2:$B$10000,$A42) -> 67.7675 | G42: =SUMIFS(Fixed!G$2:G$10000,Fixed!$B$2:$B$10000,$A42) -> 94.9761 | H42: =SUMIFS(Fixed!H$2:H$10000,Fixed!$B$2:$B$10000,$A42) -> 94.9761 | I42: =SUMIFS(Fixed!I$2:I$10000,Fixed!$B$2:$B$10000,$A42) -> 94.9761 | J42: =SUMIFS(Fixed!J$2:J$10000,Fixed!$B$2:$B$10000,$A42) -> 162.0602 | ... AG42: =SUMIFS(Fixed!AG$2:AG$10000,Fixed!$B$2:$B$10000,$A42) -> 514.0482
A43: PHL_POW_PP_COAL_CCS | C43: =SUMIFS(Fixed!C$2:C$10000,Fixed!$B$2:$B$10000,$A43) -> 0 | D43: =SUMIFS(Fixed!D$2:D$10000,Fixed!$B$2:$B$10000,$A43) -> 0 | E43: =SUMIFS(Fixed!E$2:E$10000,Fixed!$B$2:$B$10000,$A43) -> 0 | F43: =SUMIFS(Fixed!F$2:F$10000,Fixed!$B$2:$B$10000,$A43) -> 0 | G43: =SUMIFS(Fixed!G$2:G$10000,Fixed!$B$2:$B$10000,$A43) -> 0 | H43: =SUMIFS(Fixed!H$2:H$10000,Fixed!$B$2:$B$10000,$A43) -> 0 | I43: =SUMIFS(Fixed!I$2:I$10000,Fixed!$B$2:$B$10000,$A43) -> 0 | J43: =SUMIFS(Fixed!J$2:J$10000,Fixed!$B$2:$B$10000,$A43) -> 0 | ... AG43: =SUMIFS(Fixed!AG$2:AG$10000,Fixed!$B$2:$B$10000,$A43) -> 0
A44: PHL_POW_PP_H2 | C44: =SUMIFS(Fixed!C$2:C$10000,Fixed!$B$2:$B$10000,$A44) -> 0 | D44: =SUMIFS(Fixed!D$2:D$10000,Fixed!$B$2:$B$10000,$A44) -> 0 | E44: =SUMIFS(Fixed!E$2:E$10000,Fixed!$B$2:$B$10000,$A44) -> 0 | F44: =SUMIFS(Fixed!F$2:F$10000,Fixed!$B$2:$B$10000,$A44) -> 0 | G44: =SUMIFS(Fixed!G$2:G$10000,Fixed!$B$2:$B$10000,$A44) -> 0 | H44: =SUMIFS(Fixed!H$2:H$10000,Fixed!$B$2:$B$10000,$A44) -> 0 | I44: =SUMIFS(Fixed!I$2:I$10000,Fixed!$B$2:$B$10000,$A44) -> 0 | J44: =SUMIFS(Fixed!J$2:J$10000,Fixed!$B$2:$B$10000,$A44) -> 0 | ... AG44: =SUMIFS(Fixed!AG$2:AG$10000,Fixed!$B$2:$B$10000,$A44) -> 0
A45: PHL_POW_PP_HY_LA | C45: =SUMIFS(Fixed!C$2:C$10000,Fixed!$B$2:$B$10000,$A45) -> 191.6825 | D45: =SUMIFS(Fixed!D$2:D$10000,Fixed!$B$2:$B$10000,$A45) -> 287.1673 | E45: =SUMIFS(Fixed!E$2:E$10000,Fixed!$B$2:$B$10000,$A45) -> 287.7616 | F45: =SUMIFS(Fixed!F$2:F$10000,Fixed!$B$2:$B$10000,$A45) -> 289.5109 | G45: =SUMIFS(Fixed!G$2:G$10000,Fixed!$B$2:$B$10000,$A45) -> 290.8266 | H45: =SUMIFS(Fixed!H$2:H$10000,Fixed!$B$2:$B$10000,$A45) -> 290.8266 | I45: =SUMIFS(Fixed!I$2:I$10000,Fixed!$B$2:$B$10000,$A45) -> 290.8266 | J45: =SUMIFS(Fixed!J$2:J$10000,Fixed!$B$2:$B$10000,$A45) -> 290.8266 | ... AG45: =SUMIFS(Fixed!AG$2:AG$10000,Fixed!$B$2:$B$10000,$A45) -> 289.9744
A46: PHL_POW_PP_NGCC | C46: =SUMIFS(Fixed!C$2:C$10000,Fixed!$B$2:$B$10000,$A46) -> 0 | D46: =SUMIFS(Fixed!D$2:D$10000,Fixed!$B$2:$B$10000,$A46) -> 0 | E46: =SUMIFS(Fixed!E$2:E$10000,Fixed!$B$2:$B$10000,$A46) -> 0 | F46: =SUMIFS(Fixed!F$2:F$10000,Fixed!$B$2:$B$10000,$A46) -> 0 | G46: =SUMIFS(Fixed!G$2:G$10000,Fixed!$B$2:$B$10000,$A46) -> 0 | H46: =SUMIFS(Fixed!H$2:H$10000,Fixed!$B$2:$B$10000,$A46) -> 19.0192 | I46: =SUMIFS(Fixed!I$2:I$10000,Fixed!$B$2:$B$10000,$A46) -> 19.0192 | J46: =SUMIFS(Fixed!J$2:J$10000,Fixed!$B$2:$B$10000,$A46) -> 19.0192 | ... AG46: =SUMIFS(Fixed!AG$2:AG$10000,Fixed!$B$2:$B$10000,$A46) -> 217.4155
A47: PHL_POW_PP_NGCC_CCS | C47: =SUMIFS(Fixed!C$2:C$10000,Fixed!$B$2:$B$10000,$A47) -> 0 | D47: =SUMIFS(Fixed!D$2:D$10000,Fixed!$B$2:$B$10000,$A47) -> 0 | E47: =SUMIFS(Fixed!E$2:E$10000,Fixed!$B$2:$B$10000,$A47) -> 0 | F47: =SUMIFS(Fixed!F$2:F$10000,Fixed!$B$2:$B$10000,$A47) -> 0 | G47: =SUMIFS(Fixed!G$2:G$10000,Fixed!$B$2:$B$10000,$A47) -> 0 | H47: =SUMIFS(Fixed!H$2:H$10000,Fixed!$B$2:$B$10000,$A47) -> 0 | I47: =SUMIFS(Fixed!I$2:I$10000,Fixed!$B$2:$B$10000,$A47) -> 0 | J47: =SUMIFS(Fixed!J$2:J$10000,Fixed!$B$2:$B$10000,$A47) -> 0 | ... AG47: =SUMIFS(Fixed!AG$2:AG$10000,Fixed!$B$2:$B$10000,$A47) -> 0
A48: PHL_POW_PP_NU | C48: =SUMIFS(Fixed!C$2:C$10000,Fixed!$B$2:$B$10000,$A48) -> 0 | D48: =SUMIFS(Fixed!D$2:D$10000,Fixed!$B$2:$B$10000,$A48) -> 0 | E48: =SUMIFS(Fixed!E$2:E$10000,Fixed!$B$2:$B$10000,$A48) -> 0 | F48: =SUMIFS(Fixed!F$2:F$10000,Fixed!$B$2:$B$10000,$A48) -> 0 | G48: =SUMIFS(Fixed!G$2:G$10000,Fixed!$B$2:$B$10000,$A48) -> 0 | H48: =SUMIFS(Fixed!H$2:H$10000,Fixed!$B$2:$B$10000,$A48) -> 0 | I48: =SUMIFS(Fixed!I$2:I$10000,Fixed!$B$2:$B$10000,$A48) -> 0 | J48: =SUMIFS(Fixed!J$2:J$10000,Fixed!$B$2:$B$10000,$A48) -> 0 | ... AG48: =SUMIFS(Fixed!AG$2:AG$10000,Fixed!$B$2:$B$10000,$A48) -> 0
A49: PHL_POW_PP_NUSMR | C49: =SUMIFS(Fixed!C$2:C$10000,Fixed!$B$2:$B$10000,$A49) -> 0 | D49: =SUMIFS(Fixed!D$2:D$10000,Fixed!$B$2:$B$10000,$A49) -> 0 | E49: =SUMIFS(Fixed!E$2:E$10000,Fixed!$B$2:$B$10000,$A49) -> 0 | F49: =SUMIFS(Fixed!F$2:F$10000,Fixed!$B$2:$B$10000,$A49) -> 0 | G49: =SUMIFS(Fixed!G$2:G$10000,Fixed!$B$2:$B$10000,$A49) -> 0 | H49: =SUMIFS(Fixed!H$2:H$10000,Fixed!$B$2:$B$10000,$A49) -> 0 | I49: =SUMIFS(Fixed!I$2:I$10000,Fixed!$B$2:$B$10000,$A49) -> 0 | J49: =SUMIFS(Fixed!J$2:J$10000,Fixed!$B$2:$B$10000,$A49) -> 0 | ... AG49: =SUMIFS(Fixed!AG$2:AG$10000,Fixed!$B$2:$B$10000,$A49) -> 4436.4241
... A55: PHL_POW_TD | C55: =SUMIFS(Fixed!C$2:C$10000,Fixed!$B$2:$B$10000,$A55) -> 0 | D55: =SUMIFS(Fixed!D$2:D$10000,Fixed!$B$2:$B$10000,$A55) -> 0 | E55: =SUMIFS(Fixed!E$2:E$10000,Fixed!$B$2:$B$10000,$A55) -> 0 | F55: =SUMIFS(Fixed!F$2:F$10000,Fixed!$B$2:$B$10000,$A55) -> 0 | G55: =SUMIFS(Fixed!G$2:G$10000,Fixed!$B$2:$B$10000,$A55) -> 0 | H55: =SUMIFS(Fixed!H$2:H$10000,Fixed!$B$2:$B$10000,$A55) -> 0 | I55: =SUMIFS(Fixed!I$2:I$10000,Fixed!$B$2:$B$10000,$A55) -> 0 | J55: =SUMIFS(Fixed!J$2:J$10000,Fixed!$B$2:$B$10000,$A55) -> 0 | ... AG55: =SUMIFS(Fixed!AG$2:AG$10000,Fixed!$B$2:$B$10000,$A55) -> 0
A58: Capital Investments (M.USD) | C58: 2020 | D58: 2021 | E58: 2022 | F58: 2023 | G58: 2024 | H58: 2025 | I58: 2026 | J58: 2027 | K58: 2028 | L58: 2029 | M58: 2030 | N58: 2031 | O58: 2032 | P58: 2033 | Q58: 2034 | R58: 2035 | S58: 2036 | T58: 2037 | U58: 2038 | V58: 2039 | W58: 2040 | X58: 2041 | Y58: 2042 | Z58: 2043 | AA58: 2044 | AB58: 2045 | AC58: 2046 | AD58: 2047 | AE58: 2048 | AF58: 2049 | AG58: 2050
A59: PHL_POW_CHP_BIOM_OLD | C59: =SUMIFS(Capital_Investments!C$2:C$10000,Capital_Investments!$B$2:$B$10000,$A59) -> 0 | D59: =SUMIFS(Capital_Investments!D$2:D$10000,Capital_Investments!$B$2:$B$10000,$A59) -> 0 | E59: =SUMIFS(Capital_Investments!E$2:E$10000,Capital_Investments!$B$2:$B$10000,$A59) -> 369 | F59: =SUMIFS(Capital_Investments!F$2:F$10000,Capital_Investments!$B$2:$B$10000,$A59) -> 27 | G59: =SUMIFS(Capital_Investments!G$2:G$10000,Capital_Investments!$B$2:$B$10000,$A59) -> 44.55 | H59: =SUMIFS(Capital_Investments!H$2:H$10000,Capital_Investments!$B$2:$B$10000,$A59) -> 0 | I59: =SUMIFS(Capital_Investments!I$2:I$10000,Capital_Investments!$B$2:$B$10000,$A59) -> 0 | J59: =SUMIFS(Capital_Investments!J$2:J$10000,Capital_Investments!$B$2:$B$10000,$A59) -> 0 | ... AG59: =SUMIFS(Capital_Investments!AG$2:AG$10000,Capital_Investments!$B$2:$B$10000,$A59) -> 0
...

Sheet Variable
A1: REGION | B1: TECHNOLOGY | C1: 2020 | D1: 2021 | E1: 2022 | F1: 2023 | G1: 2024 | H1: 2025 | I1: 2026 | J1: 2027 | K1: 2028 | L1: 2029 | M1: 2030 | N1: 2031 | O1: 2032 | P1: 2033 | Q1: 2034 | R1: 2035 | S1: 2036 | T1: 2037 | U1: 2038 | V1: 2039 | W1: 2040 | X1: 2041 | Y1: 2042 | Z1: 2043 | AA1: 2044 | AB1: 2045 | AC1: 2046 | AD1: 2047 | AE1: 2048 | AF1: 2049 | AG1: 2050
B2: PHL_AGR_FAC | C2: 0.0009 | D2: 0.001 | E2: 0.001 | F2: 0.001 | G2: 0.001 | H2: 0.001 | I2: 0.0011 | J2: 0.0011 | K2: 0.0011 | L2: 0.0011 | M2: 0.0011 | N2: 0.0012 | O2: 0.0012 | P2: 0.0012 | Q2: 0.0013 | R2: 0.0013 | S2: 0.0013 | T2: 0.0013 | U2: 0.0014 | V2: 0.0014 | W2: 0.0014 | X2: 0.0011 | Y2: 0.001 | Z2: 0.001 | AA2: 0.0009 | AB2: 0.0008 | AC2: 0.0008 | AD2: 0.0007 | AE2: 0.0006 | AF2: 0.0006 | AG2: 0.0018 | AH2: 0.0019 | AI2: 0.0019 | AJ2: 0.0019
B3: PHL_AGR_HEAT_BIOM | C3: 0 | D3: 0 | E3: 0 | F3: 0 | G3: 0 | H3: 0 | I3: 0 | J3: 0 | K3: 0 | L3: 0 | M3: 0 | N3: 0 | O3: 0 | P3: 0 | Q3: 0 | R3: 0 | S3: 0 | T3: 0 | U3: 0 | V3: 0 | W3: 0 | X3: 0 | Y3: 0 | Z3: 0 | AA3: 0 | AB3: 0 | AC3: 0 | AD3: 0 | AE3: 0 | AF3: 0 | AG3: 0 | AH3: 0 | AI3: 0 | AJ3: 0
B4: PHL_AGR_HEAT_COAL | C4: 0 | D4: 0 | E4: 0 | F4: 0 | G4: 0 | H4: 0 | I4: 0 | J4: 0 | K4: 0 | L4: 0 | M4: 0 | N4: 0 | O4: 0 | P4: 0 | Q4: 0 | R4: 0 | S4: 0 | T4: 0 | U4: 0 | V4: 0 | W4: 0 | X4: 0 | Y4: 0 | Z4: 0 | AA4: 0 | AB4: 0 | AC4: 0 | AD4: 0 | AE4: 0 | AF4: 0 | AG4: 0 | AH4: 0 | AI4: 0 | AJ4: 0
B5: PHL_AGR_HEAT_ELE | C5: 0 | D5: 0 | E5: 0 | F5: 0 | G5: 0 | H5: 0 | I5: 0 | J5: 0 | K5: 0 | L5: 0 | M5: 0 | N5: 0 | O5: 0 | P5: 0 | Q5: 0 | R5: 0 | S5: 0 | T5: 0 | U5: 0 | V5: 0 | W5: 0 | X5: 0 | Y5: 0 | Z5: 0 | AA5: 0 | AB5: 0 | AC5: 0 | AD5: 0 | AE5: 0 | AF5: 0 | AG5: 0 | AH5: 0 | AI5: 0 | AJ5: 0
B6: PHL_AGR_HEAT_NG | C6: 0.0008 | D6: 0.0008 | E6: 0.0008 | F6: 0.0008 | G6: 0.0009 | H6: 0.0009 | I6: 0.0009 | J6: 0.0009 | K6: 0.0009 | L6: 0.001 | M6: 0.001 | N6: 0.001 | O6: 0.001 | P6: 0.0011 | Q6: 0.0011 | R6: 0.0011 | S6: 0.0011 | T6: 0.0012 | U6: 0.0012 | V6: 0.0012 | W6: 0.0013 | X6: 0.0012 | Y6: 0.0011 | Z6: 0.001 | AA6: 0.0009 | AB6: 0.0009 | AC6: 0.0008 | AD6: 0.0008 | AE6: 0.0007 | AF6: 0.0006 | AG6: 0.0017 | AH6: 0.0018 | AI6: 0.0018 | AJ6: 0.0019
B7: PHL_AGR_HEAT_OIL | C7: 0.0001 | D7: 0.0001 | E7: 0.0001 | F7: 0.0001 | G7: 0.0001 | H7: 0.0001 | I7: 0.0001 | J7: 0.0001 | K7: 0.0001 | L7: 0.0001 | M7: 0.0001 | N7: 0.0001 | O7: 0.0001 | P7: 0.0001 | Q7: 0.0001 | R7: 0.0001 | S7: 0.0001 | T7: 0.0001 | U7: 0.0001 | V7: 0.0001 | W7: 0.0001 | X7: 0.0001 | Y7: 0.0001 | Z7: 0.0001 | AA7: 0.0001 | AB7: 0 | AC7: 0 | AD7: 0 | AE7: 0 | AF7: 0 | AG7: 0 | AH7: 0 | AI7: 0 | AJ7: 0
B8: PHL_AGR_MOT_ELE | C8: 0 | D8: 0 | E8: 0 | F8: 0 | G8: 0 | H8: 0 | I8: 0 | J8: 0 | K8: 0 | L8: 0 | M8: 0 | N8: 0 | O8: 0 | P8: 0 | Q8: 0 | R8: 0 | S8: 0 | T8: 0 | U8: 0 | V8: 0 | W8: 0 | X8: 0 | Y8: 0 | Z8: 0 | AA8: 0 | AB8: 0 | AC8: 0 | AD8: 0 | AE8: 0 | AF8: 0 | AG8: 0 | AH8: 0 | AI8: 0 | AJ8: 0
B9: PHL_AGR_MOT_LIQ | C9: 0.0008 | D9: 0.0008 | E9: 0.0008 | F9: 0.0008 | G9: 0.0009 | H9: 0.0009 | I9: 0.0009 | J9: 0.0009 | K9: 0.0009 | L9: 0.001 | M9: 0.001 | N9: 0.001 | O9: 0.001 | P9: 0.001 | Q9: 0.0011 | R9: 0.0011 | S9: 0.0011 | T9: 0.0011 | U9: 0.0012 | V9: 0.0012 | W9: 0.0012 | X9: 0.0012 | Y9: 0.0013 | Z9: 0.0013 | AA9: 0.0013 | AB9: 0.0014 | AC9: 0.0014 | AD9: 0.0014 | AE9: 0.0015 | AF9: 0.0015 | AG9: 0.0015 | AH9: 0.0016 | AI9: 0.0016 | AJ9: 0.0017
