Workbook

Sheet Grid_cost_Base
A1: =Cost_of_ELCgen!A149 -> Calculations | C1: =Cost_of_ELCgen!C149 -> 2020 | D1: =Cost_of_ELCgen!D149 -> 2021 | E1: =Cost_of_ELCgen!E149 -> 2022 | F1: =Cost_of_ELCgen!F149 -> 2023 | G1: =Cost_of_ELCgen!G149 -> 2024 | H1: =Cost_of_ELCgen!H149 -> 2025 | I1: =Cost_of_ELCgen!I149 -> 2026 | J1: =Cost_of_ELCgen!J149 -> 2027 | ... AG1: =Cost_of_ELCgen!AG149 -> 2050
A2: =Cost_of_ELCgen!A150 -> Operating O&M costs | C2: =Cost_of_ELCgen!C150 -> 4162.8638 | D2: =Cost_of_ELCgen!D150 -> 3853.8406 | E2: =Cost_of_ELCgen!E150 -> 4014.6511 | F2: =Cost_of_ELCgen!F150 -> 4210.1257 | G2: =Cost_of_ELCgen!G150 -> 4252.9125 | H2: =Cost_of_ELCgen!H150 -> 4518.7706 | I2: =Cost_of_ELCgen!I150 -> 4679.6315 | J2: =Cost_of_ELCgen!J150 -> 4872.7074 | ... AG2: =Cost_of_ELCgen!AG150 -> 10472.025
A3: =Cost_of_ELCgen!A151 -> Annualized Investment costs | C3: =Cost_of_ELCgen!C151 -> 143.48784 | D3: =Cost_of_ELCgen!D151 -> 337.45956 | E3: =Cost_of_ELCgen!E151 -> 538.60559 | F3: =Cost_of_ELCgen!F151 -> 554.30562 | G3: =Cost_of_ELCgen!G151 -> 684.58792 | H3: =Cost_of_ELCgen!H151 -> 757.97001 | I3: =Cost_of_ELCgen!I151 -> 757.97001 | J3: =Cost_of_ELCgen!J151 -> 826.35984 | ... AG3: =Cost_of_ELCgen!AG151 -> 7599.7526
A4: =Cost_of_ELCgen!A152 -> CO2 costs | C4: =Cost_of_ELCgen!C152 -> 0 | D4: =Cost_of_ELCgen!D152 -> 0 | E4: =Cost_of_ELCgen!E152 -> 0 | F4: =Cost_of_ELCgen!F152 -> 0 | G4: =Cost_of_ELCgen!G152 -> 0 | H4: =Cost_of_ELCgen!H152 -> 0 | I4: =Cost_of_ELCgen!I152 -> 0 | J4: =Cost_of_ELCgen!J152 -> 0 | ... AG4: =Cost_of_ELCgen!AG152 -> 0
A5: =Cost_of_ELCgen!A153 -> Total Costs (Million USD) | C5: =Cost_of_ELCgen!C153 -> 4306.3517 | D5: =Cost_of_ELCgen!D153 -> 4191.3001 | E5: =Cost_of_ELCgen!E153 -> 4553.2567 | F5: =Cost_of_ELCgen!F153 -> 4764.4313 | G5: =Cost_of_ELCgen!G153 -> 4937.5004 | H5: =Cost_of_ELCgen!H153 -> 5276.7406 | I5: =Cost_of_ELCgen!I153 -> 5437.6015 | J5: =Cost_of_ELCgen!J153 -> 5699.0672 | ... AG5: =Cost_of_ELCgen!AG153 -> 18071.778
A6: =Cost_of_ELCgen!A154 -> Generation (PJ->GWh), Before Transmission losses | C6: =Cost_of_ELCgen!C154 -> 101777.47 | D6: =Cost_of_ELCgen!D154 -> 101856.03 | E6: =Cost_of_ELCgen!E154 -> 107092.5 | F6: =Cost_of_ELCgen!F154 -> 111523.03 | G6: =Cost_of_ELCgen!G154 -> 116469.06 | H6: =Cost_of_ELCgen!H154 -> 121697.72 | I6: =Cost_of_ELCgen!I154 -> 127969 | J6: =Cost_of_ELCgen!J154 -> 134326.11 | ... AG6: =Cost_of_ELCgen!AG154 -> 346335.28
A7: =Cost_of_ELCgen!A155 -> Average electricity cost (USD/kWh) - Base | C7: =Cost_of_ELCgen!C155 -> 0.042311443 | D7: =Cost_of_ELCgen!D155 -> 0.04114926 | E7: =Cost_of_ELCgen!E155 -> 0.042517046 | F7: =Cost_of_ELCgen!F155 -> 0.042721503 | G7: =Cost_of_ELCgen!G155 -> 0.042393238 | H7: =Cost_of_ELCgen!H155 -> 0.043359403 | I7: =Cost_of_ELCgen!I155 -> 0.042491553 | J7: =Cost_of_ELCgen!J155 -> 0.042427099 | ... AG7: =Cost_of_ELCgen!AG155 -> 0.052180008

Sheet Investments_Base
A1: Base Scenario
A3: Variable | C3: 2020 | D3: 2021 | E3: 2022 | F3: 2023 | G3: 2024 | H3: 2025 | I3: 2026 | J3: 2027 | K3: 2028 | L3: 2029 | M3: 2030 | N3: 2031 | O3: 2032 | P3: 2033 | Q3: 2034 | R3: 2035 | S3: 2036 | T3: 2037 | U3: 2038 | V3: 2039 | W3: 2040 | X3: 2041 | Y3: 2042 | Z3: 2043 | AA3: 2044 | AB3: 2045 | AC3: 2046 | AD3: 2047 | AE3: 2048 | AF3: 2049 | AG3: 2050
A4: =Cost_of_ELCgen!A77 -> Total Capital Investment (Million USD) | C4: =Cost_of_ELCgen!C77 -> 2844.1751 | D4: =Cost_of_ELCgen!D77 -> 3215.6945 | E4: =Cost_of_ELCgen!E77 -> 3334.6461 | F4: =Cost_of_ELCgen!F77 -> 277.5919 | G4: =Cost_of_ELCgen!G77 -> 2053.5828 | H4: =Cost_of_ELCgen!H77 -> 1168.3836 | I4: =Cost_of_ELCgen!I77 -> 0 | J4: =Cost_of_ELCgen!J77 -> 1012.0767 | ... AG4: =Cost_of_ELCgen!AG77 -> 33451.744
A5: =Cost_of_ELCgen!A98 -> Total Annualized Investments (Million USD) | C5: =Cost_of_ELCgen!C98 -> 143.48784 | D5: =Cost_of_ELCgen!D98 -> 337.45956 | E5: =Cost_of_ELCgen!E98 -> 538.60559 | F5: =Cost_of_ELCgen!F98 -> 554.30562 | G5: =Cost_of_ELCgen!G98 -> 684.58792 | H5: =Cost_of_ELCgen!H98 -> 757.97001 | I5: =Cost_of_ELCgen!I98 -> 757.97001 | J5: =Cost_of_ELCgen!J98 -> 826.35984 | ... AG5: =Cost_of_ELCgen!AG98 -> 7599.7526

Sheet Cost_of_ELCgen
A1: Philippines
A3: AnnualFixedOperatingCost + AnnualVariableOperating Cost (Million USD) | C3: 2020 | D3: 2021 | E3: 2022 | F3: 2023 | G3: 2024 | H3: 2025 | I3: 2026 | J3: 2027 | K3: 2028 | L3: 2029 | M3: 2030 | N3: 2031 | O3: 2032 | P3: 2033 | Q3: 2034 | R3: 2035 | S3: 2036 | T3: 2037 | U3: 2038 | V3: 2039 | W3: 2040 | X3: 2041 | Y3: 2042 | Z3: 2043 | AA3: 2044 | AB3: 2045 | AC3: 2046 | AD3: 2047 | AE3: 2048 | AF3: 2049 | AG3: 2050
A4: TOTAL (Fixed & Variable) | C4: =SUM(C6:C9)+SUM(C38:C54) -> 12310.832 | D4: =SUM(D6:D9)+SUM(D38:D54) -> 5122.5043 | E4: =SUM(E6:E9)+SUM(E38:E54) -> 5319.9663 | F4: =SUM(F6:F9)+SUM(F38:F54) -> 5592.5476 | G4: =SUM(G6:G9)+SUM(G38:G54) -> 6742.4957 | H4: =SUM(H6:H9)+SUM(H38:H54) -> 7004.6527 | I4: =SUM(I6:I9)+SUM(I38:I54) -> 7332.7254 | J4: =SUM(J6:J9)+SUM(J38:J54) -> 7591.662 | ... AG4: =SUM(AG6:AG9)+SUM(AG38:AG54) -> 6227.5159
A5: VARIABLE
A6: PHL_PRO_EXTR_NG | C6: =SUMIFS(Variable!C$2:C$10000,Variable!$B$2:$B$10000,$A6) -> 1261.3245 | D6: =SUMIFS(Variable!D$2:D$10000,Variable!$B$2:$B$10000,$A6) -> 240.2289 | E6: =SUMIFS(Variable!E$2:E$10000,Variable!$B$2:$B$10000,$A6) -> 262.3222 | F6: =SUMIFS(Variable!F$2:F$10000,Variable!$B$2:$B$10000,$A6) -> 330.6415 | G6: =SUMIFS(Variable!G$2:G$10000,Variable!$B$2:$B$10000,$A6) -> 1439.8781 | H6: =SUMIFS(Variable!H$2:H$10000,Variable!$B$2:$B$10000,$A6) -> 1550.1288 | I6: =SUMIFS(Variable!I$2:I$10000,Variable!$B$2:$B$10000,$A6) -> 1709.9739 | J6: =SUMIFS(Variable!J$2:J$10000,Variable!$B$2:$B$10000,$A6) -> 1766.589 | ... AG6: =SUMIFS(Variable!AG$2:AG$10000,Variable!$B$2:$B$10000,$A6) -> 3569.0526
A7: PHL_PRO_EXTR_OIL | C7: =SUMIFS(Variable!C$2:C$10000,Variable!$B$2:$B$10000,$A7) -> 3103.7145 | D7: =SUMIFS(Variable!D$2:D$10000,Variable!$B$2:$B$10000,$A7) -> 0 | E7: =SUMIFS(Variable!E$2:E$10000,Variable!$B$2:$B$10000,$A7) -> 0 | F7: =SUMIFS(Variable!F$2:F$10000,Variable!$B$2:$B$10000,$A7) -> 0 | G7: =SUMIFS(Variable!G$2:G$10000,Variable!$B$2:$B$10000,$A7) -> 0 | H7: =SUMIFS(Variable!H$2:H$10000,Variable!$B$2:$B$10000,$A7) -> 0 | I7: =SUMIFS(Variable!I$2:I$10000,Variable!$B$2:$B$10000,$A7) -> 0 | J7: =SUMIFS(Variable!J$2:J$10000,Variable!$B$2:$B$10000,$A7) -> 0 | ... AG7: =SUMIFS(Variable!AG$2:AG$10000,Variable!$B$2:$B$10000,$A7) -> 0
A8: PHL_PRO_EXTR_COAL | C8: =SUMIFS(Variable!C$2:C$10000,Variable!$B$2:$B$10000,$A8) -> 2023.5934 | D8: =SUMIFS(Variable!D$2:D$10000,Variable!$B$2:$B$10000,$A8) -> 3760.7493 | E8: =SUMIFS(Variable!E$2:E$10000,Variable!$B$2:$B$10000,$A8) -> 3887.391 | F8: =SUMIFS(Variable!F$2:F$10000,Variable!$B$2:$B$10000,$A8) -> 4124.4119 | G8: =SUMIFS(Variable!G$2:G$10000,Variable!$B$2:$B$10000,$A8) -> 4180.0101 | H8: =SUMIFS(Variable!H$2:H$10000,Variable!$B$2:$B$10000,$A8) -> 4306.9405 | I8: =SUMIFS(Variable!I$2:I$10000,Variable!$B$2:$B$10000,$A8) -> 4476.501 | J8: =SUMIFS(Variable!J$2:J$10000,Variable!$B$2:$B$10000,$A8) -> 4650.6059 | ... AG8: =SUMIFS(Variable!AG$2:AG$10000,Variable!$B$2:$B$10000,$A8) -> 0
A9: PHL_PRO_PROC_BIOM | C9: =SUMIFS(Variable!C$2:C$10000,Variable!$B$2:$B$10000,$A9) -> 4868.8589 | D9: =SUMIFS(Variable!D$2:D$10000,Variable!$B$2:$B$10000,$A9) -> 28.0453 | E9: =SUMIFS(Variable!E$2:E$10000,Variable!$B$2:$B$10000,$A9) -> 28.2742 | F9: =SUMIFS(Variable!F$2:F$10000,Variable!$B$2:$B$10000,$A9) -> 28.5122 | G9: =SUMIFS(Variable!G$2:G$10000,Variable!$B$2:$B$10000,$A9) -> 0 | H9: =SUMIFS(Variable!H$2:H$10000,Variable!$B$2:$B$10000,$A9) -> 0 | I9: =SUMIFS(Variable!I$2:I$10000,Variable!$B$2:$B$10000,$A9) -> 0 | J9: =SUMIFS(Variable!J$2:J$10000,Variable!$B$2:$B$10000,$A9) -> 0 | ... AG9: =SUMIFS(Variable!AG$2:AG$10000,Variable!$B$2:$B$10000,$A9) -> 0
A10: PHL_POW_CHP_BIOM_OLD | C10: =SUMIFS(Variable!C$2:C$10000,Variable!$B$2:$B$10000,$A10) -> 0.0004 | D10: =SUMIFS(Variable!D$2:D$10000,Variable!$B$2:$B$10000,$A10) -> 0 | E10: =SUMIFS(Variable!E$2:E$10000,Variable!$B$2:$B$10000,$A10) -> 0 | F10: =SUMIFS(Variable!F$2:F$10000,Variable!$B$2:$B$10000,$A10) -> 0 | G10: =SUMIFS(Variable!G$2:G$10000,Variable!$B$2:$B$10000,$A10) -> 0 | H10: =SUMIFS(Variable!H$2:H$10000,Variable!$B$2:$B$10000,$A10) -> 0 | I10: =SUMIFS(Variable!I$2:I$10000,Variable!$B$2:$B$10000,$A10) -> 0 | J10: =SUMIFS(Variable!J$2:J$10000,Variable!$B$2:$B$10000,$A10) -> 0 | ... AG10: =SUMIFS(Variable!AG$2:AG$10000,Variable!$B$2:$B$10000,$A10) -> 0
A11: PHL_POW_CHP_COAL_OLD | C11: =SUMIFS(Variable!C$2:C$10000,Variable!$B$2:$B$10000,$A11) -> 0.0209 | D11: =SUMIFS(Variable!D$2:D$10000,Variable!$B$2:$B$10000,$A11) -> 0.0267 | E11: =SUMIFS(Variable!E$2:E$10000,Variable!$B$2:$B$10000,$A11) -> 0.026 | F11: =SUMIFS(Variable!F$2:F$10000,Variable!$B$2:$B$10000,$A11) -> 0.0282 | G11: =SUMIFS(Variable!G$2:G$10000,Variable!$B$2:$B$10000,$A11) -> 0.027 | H11: =SUMIFS(Variable!H$2:H$10000,Variable!$B$2:$B$10000,$A11) -> 0.028 | I11: =SUMIFS(Variable!I$2:I$10000,Variable!$B$2:$B$10000,$A11) -> 0.0295 | J11: =SUMIFS(Variable!J$2:J$10000,Variable!$B$2:$B$10000,$A11) -> 0.0295 | ... AG11: =SUMIFS(Variable!AG$2:AG$10000,Variable!$B$2:$B$10000,$A11) -> 0.0082
A12: PHL_POW_GEO_OLD | C12: =SUMIFS(Variable!C$2:C$10000,Variable!$B$2:$B$10000,$A12) -> 0.0039 | D12: =SUMIFS(Variable!D$2:D$10000,Variable!$B$2:$B$10000,$A12) -> 0.004 | E12: =SUMIFS(Variable!E$2:E$10000,Variable!$B$2:$B$10000,$A12) -> 0.004 | F12: =SUMIFS(Variable!F$2:F$10000,Variable!$B$2:$B$10000,$A12) -> 0.003 | G12: =SUMIFS(Variable!G$2:G$10000,Variable!$B$2:$B$10000,$A12) -> 0.003 | H12: =SUMIFS(Variable!H$2:H$10000,Variable!$B$2:$B$10000,$A12) -> 0.0031 | I12: =SUMIFS(Variable!I$2:I$10000,Variable!$B$2:$B$10000,$A12) -> 0.0031 | J12: =SUMIFS(Variable!J$2:J$10000,Variable!$B$2:$B$10000,$A12) -> 0.0031 | ... AG12: =SUMIFS(Variable!AG$2:AG$10000,Variable!$B$2:$B$10000,$A12) -> 0.0004
A13: PHL_POW_PP_BIOM_CCS | C13: =SUMIFS(Variable!C$2:C$10000,Variable!$B$2:$B$10000,$A13) -> 0 | D13: =SUMIFS(Variable!D$2:D$10000,Variable!$B$2:$B$10000,$A13) -> 0 | E13: =SUMIFS(Variable!E$2:E$10000,Variable!$B$2:$B$10000,$A13) -> 0 | F13: =SUMIFS(Variable!F$2:F$10000,Variable!$B$2:$B$10000,$A13) -> 0 | G13: =SUMIFS(Variable!G$2:G$10000,Variable!$B$2:$B$10000,$A13) -> 0 | H13: =SUMIFS(Variable!H$2:H$10000,Variable!$B$2:$B$10000,$A13) -> 0 | I13: =SUMIFS(Variable!I$2:I$10000,Variable!$B$2:$B$10000,$A13) -> 0 | J13: =SUMIFS(Variable!J$2:J$10000,Variable!$B$2:$B$10000,$A13) -> 0 | ... AG13: =SUMIFS(Variable!AG$2:AG$10000,Variable!$B$2:$B$10000,$A13) -> 0
A14: PHL_POW_PP_COAL | C14: =SUMIFS(Variable!C$2:C$10000,Variable!$B$2:$B$10000,$A14) -> 0 | D14: =SUMIFS(Variable!D$2:D$10000,Variable!$B$2:$B$10000,$A14) -> 0.0023 | E14: =SUMIFS(Variable!E$2:E$10000,Variable!$B$2:$B$10000,$A14) -> 0.0047 | F14: =SUMIFS(Variable!F$2:F$10000,Variable!$B$2:$B$10000,$A14) -> 0.0047 | G14: =SUMIFS(Variable!G$2:G$10000,Variable!$B$2:$B$10000,$A14) -> 0.0066 | H14: =SUMIFS(Variable!H$2:H$10000,Variable!$B$2:$B$10000,$A14) -> 0.0066 | I14: =SUMIFS(Variable!I$2:I$10000,Variable!$B$2:$B$10000,$A14) -> 0.0066 | J14: =SUMIFS(Variable!J$2:J$10000,Variable!$B$2:$B$10000,$A14) -> 0.0087 | ... AG14: =SUMIFS(Variable!AG$2:AG$10000,Variable!$B$2:$B$10000,$A14) -> 0.0713
A15: PHL_POW_PP_COAL_CCS | C15: =SUMIFS(Variable!C$2:C$10000,Variable!$B$2:$B$10000,$A15) -> 0 | D15: =SUMIFS(Variable!D$2:D$10000,Variable!$B$2:$B$10000,$A15) -> 0 | E15: =SUMIFS(Variable!E$2:E$10000,Variable!$B$2:$B$10000,$A15) -> 0 | F15: =SUMIFS(Variable!F$2:F$10000,Variable!$B$2:$B$10000,$A15) -> 0 | G15: =SUMIFS(Variable!G$2:G$10000,Variable!$B$2:$B$10000,$A15) -> 0 | H15: =SUMIFS(Variable!H$2:H$10000,Variable!$B$2:$B$10000,$A15) -> 0 | I15: =SUMIFS(Variable!I$2:I$10000,Variable!$B$2:$B$10000,$A15) -> 0 | J15: =SUMIFS(Variable!J$2:J$10000,Variable!$B$2:$B$10000,$A15) -> 0 | ... AG15: =SUMIFS(Variable!AG$2:AG$10000,Variable!$B$2:$B$10000,$A15) -> 0
A16: PHL_POW_PP_H2 | C16: =SUMIFS(Variable!C$2:C$10000,Variable!$B$2:$B$10000,$A16) -> 0 | D16: =SUMIFS(Variable!D$2:D$10000,Variable!$B$2:$B$10000,$A16) -> 0 | E16: =SUMIFS(Variable!E$2:E$10000,Variable!$B$2:$B$10000,$A16) -> 0 | F16: =SUMIFS(Variable!F$2:F$10000,Variable!$B$2:$B$10000,$A16) -> 0 | G16: =SUMIFS(Variable!G$2:G$10000,Variable!$B$2:$B$10000,$A16) -> 0 | H16: =SUMIFS(Variable!H$2:H$10000,Variable!$B$2:$B$10000,$A16) -> 0 | I16: =SUMIFS(Variable!I$2:I$10000,Variable!$B$2:$B$10000,$A16) -> 0 | J16: =SUMIFS(Variable!J$2:J$10000,Variable!$B$2:$B$10000,$A16) -> 0 | ... AG16: =SUMIFS(Variable!AG$2:AG$10000,Variable!$B$2:$B$10000,$A16) -> 0
A17: PHL_POW_PP_HY_LA | C17: =SUMIFS(Variable!C$2:C$10000,Variable!$B$2:$B$10000,$A17) -> 0.0026 | D17: =SUMIFS(Variable!D$2:D$10000,Variable!$B$2:$B$10000,$A17) -> 0.0026 | E17: =SUMIFS(Variable!E$2:E$10000,Variable!$B$2:$B$10000,$A17) -> 0.0026 | F17: =SUMIFS(Variable!F$2:F$10000,Variable!$B$2:$B$10000,$A17) -> 0.0026 | G17: =SUMIFS(Variable!G$2:G$10000,Variable!$B$2:$B$10000,$A17) -> 0.0026 | H17: =SUMIFS(Variable!H$2:H$10000,Variable!$B$2:$B$10000,$A17) -> 0.0026 | I17: =SUMIFS(Variable!I$2:I$10000,Variable!$B$2:$B$10000,$A17) -> 0.0026 | J17: =SUMIFS(Variable!J$2:J$10000,Variable!$B$2:$B$10000,$A17) -> 0.0026 | ... AG17: =SUMIFS(Variable!AG$2:AG$10000,Variable!$B$2:$B$10000,$A17) -> 0.0024
... A27: PHL_POW_TD | C27: =SUMIFS(Variable!C$2:C$10000,Variable!$B$2:$B$10000,$A27) -> 0.03 | D27: =SUMIFS(Variable!D$2:D$10000,Variable!$B$2:$B$10000,$A27) -> 0.03 | E27: =SUMIFS(Variable!E$2:E$10000,Variable!$B$2:$B$10000,$A27) -> 0.0315 | F27: =SUMIFS(Variable!F$2:F$10000,Variable!$B$2:$B$10000,$A27) -> 0.0328 | G27: =SUMIFS(Variable!G$2:G$10000,Variable!$B$2:$B$10000,$A27) -> 0.0343 | H27: =SUMIFS(Variable!H$2:H$10000,Variable!$B$2:$B$10000,$A27) -> 0.0358 | I27: =SUMIFS(Variable!I$2:I$10000,Variable!$B$2:$B$10000,$A27) -> 0.0377 | J27: =SUMIFS(Variable!J$2:J$10000,Variable!$B$2:$B$10000,$A27) -> 0.0396 | ... AG27: =SUMIFS(Variable!AG$2:AG$10000,Variable!$B$2:$B$10000,$A27) -> 0.102
A29: Only grid-connected
A30: Coal | C30: =SUM(C225,C228:C229)*C120 -> 2026.2812 | D30: =SUM(D225,D228:D229)*D120 -> 2760.2931 | E30: =SUM(E225,E228:E229)*E120 -> 2872.6021 | F30: =SUM(F225,F228:F229)*F120 -> 3101.0707 | G30: =SUM(G225,G228:G229)*G120 -> 3130.2287 | H30: =SUM(H225,H228:H229)*H120 -> 3241.6725 | I30: =SUM(I225,I228:I229)*I120 -> 3399.1631 | J30: =SUM(J225,J228:J229)*J120 -> 3563.4373 | ... AG30: =SUM(AG225,AG228:AG229)*AG120 -> 6947.5685
A31: Natural gas | C31: =SUM(C232:C233)*C122 -> 0 | D31: =SUM(D232:D233)*D122 -> 0 | E31: =SUM(E232:E233)*E122 -> 0 | F31: =SUM(F232:F233)*F122 -> 0 | G31: =SUM(G232:G233)*G122 -> 0 | H31: =SUM(H232:H233)*H122 -> 129.4351 | I31: =SUM(I232:I233)*I122 -> 134.13412 | J31: =SUM(J232:J233)*J122 -> 134.71496 | ... AG31: =SUM(AG232:AG233)*AG122 -> 865.76634
A32: Oil | C32: =C239*C121 -> 713.04759 | D32: =D239*D121 -> 0 | E32: =E239*E121 -> 0 | F32: =F239*F121 -> 0 | G32: =G239*G121 -> 0 | H32: =H239*H121 -> 0 | I32: =I239*I121 -> 0 | J32: =J239*J121 -> 0 | ... AG32: =AG239*AG121 -> 0
A33: Biomass | C33: =SUM(C224,C227)*C123 -> 370.128 | D33: =SUM(D224,D227)*D123 -> 0 | E33: =SUM(E224,E227)*E123 -> 0 | F33: =SUM(F224,F227)*F123 -> 0 | G33: =SUM(G224,G227)*G123 -> 0 | H33: =SUM(H224,H227)*H123 -> 0 | I33: =SUM(I224,I227)*I123 -> 0 | J33: =SUM(J224,J227)*J123 -> 0 | ... AG33: =SUM(AG224,AG227)*AG123 -> 0
A34: Uranium | C34: =C241*C124 -> 0 | D34: =D241*D124 -> 0 | E34: =E241*E124 -> 0 | F34: =F241*F124 -> 0 | G34: =G241*G124 -> 0 | H34: =H241*H124 -> 0 | I34: =I241*I124 -> 0 | J34: =J241*J124 -> 0 | ... AG34: =AG241*AG124 -> 0
A35: TOTAL (Fixed & Variable) | C35: =SUM(C38:C55)+SUM(C30:C34)+SUM(C10:C27) -> 4162.8638 | D35: =SUM(D38:D55)+SUM(D30:D34)+SUM(D10:D27) -> 3853.8406 | E35: =SUM(E38:E55)+SUM(E30:E34)+SUM(E10:E27) -> 4014.6511 | F35: =SUM(F38:F55)+SUM(F30:F34)+SUM(F10:F27) -> 4210.1257 | G35: =SUM(G38:G55)+SUM(G30:G34)+SUM(G10:G27) -> 4252.9125 | H35: =SUM(H38:H55)+SUM(H30:H34)+SUM(H10:H27) -> 4518.7706 | I35: =SUM(I38:I55)+SUM(I30:I34)+SUM(I10:I27) -> 4679.6315 | J35: =SUM(J38:J55)+SUM(J30:J34)+SUM(J10:J27) -> 4872.7074 | ... AG35: =SUM(AG38:AG55)+SUM(AG30:AG34)+SUM(AG10:AG27) -> 10472.025
A37: FIXED | C37: 2020 | D37: 2021 | E37: 2022 | F37: 2023 | G37: 2024 | H37: 2025 | I37: 2026 | J37: 2027 | K37: 2028 | L37: 2029 | M37: 2030 | N37: 2031 | O37: 2032 | P37: 2033 | Q37: 2034 | R37: 2035 | S37: 2036 | T37: 2037 | U37: 2038 | V37: 2039 | W37: 2040 | X37: 2041 | Y37: 2042 | Z37: 2043 | AA37: 2044 | AB37: 2045 | AC37: 2046 | AD37: 2047 | AE37: 2048 | AF37: 2049 | AG37: 2050
A38: PHL_POW_CHP_BIOM_OLD | C38: =SUMIFS(Fixed!C$2:C$10000,Fixed!$B$2:$B$10000,$A38) -> 44.748 | D38: =SUMIFS(Fixed!D$2:D$10000,Fixed!$B$2:$B$10000,$A38) -> 44.748 | E38: =SUMIFS(Fixed!E$2:E$10000,Fixed!$B$2:$B$10000,$A38) -> 52.128 | F38: =SUMIFS(Fixed!F$2:F$10000,Fixed!$B$2:$B$10000,$A38) -> 52.668 | G38: =SUMIFS(Fixed!G$2:G$10000,Fixed!$B$2:$B$10000,$A38) -> 53.559 | H38: =SUMIFS(Fixed!H$2:H$10000,Fixed!$B$2:$B$10000,$A38) -> 53.559 | I38: =SUMIFS(Fixed!I$2:I$10000,Fixed!$B$2:$B$10000,$A38) -> 53.559 | J38: =SUMIFS(Fixed!J$2:J$10000,Fixed!$B$2:$B$10000,$A38) -> 53.559 | ... AG38: =SUMIFS(Fixed!AG$2:AG$10000,Fixed!$B$2:$B$10000,$A38) -> 45.693
A39: PHL_POW_CHP_COAL_OLD | C39: =SUMIFS(Fixed!C$2:C$10000,Fixed!$B$2:$B$10000,$A39) -> 491.0355 | D39: =SUMIFS(Fixed!D$2:D$10000,Fixed!$B$2:$B$10000,$A39) -> 491.0355 | E39: =SUMIFS(Fixed!E$2:E$10000,Fixed!$B$2:$B$10000,$A39) -> 491.0355 | F39: =SUMIFS(Fixed!F$2:F$10000,Fixed!$B$2:$B$10000,$A39) -> 491.0355 | G39: =SUMIFS(Fixed!G$2:G$10000,Fixed!$B$2:$B$10000,$A39) -> 464.0355 | H39: =SUMIFS(Fixed!H$2:H$10000,Fixed!$B$2:$B$10000,$A39) -> 464.0355 | I39: =SUMIFS(Fixed!I$2:I$10000,Fixed!$B$2:$B$10000,$A39) -> 464.0355 | J39: =SUMIFS(Fixed!J$2:J$10000,Fixed!$B$2:$B$10000,$A39) -> 464.0355 | ... AG39: =SUMIFS(Fixed!AG$2:AG$10000,Fixed!$B$2:$B$10000,$A39) -> 286.461
A40: PHL_POW_GEO_OLD | C40: =SUMIFS(Fixed!C$2:C$10000,Fixed!$B$2:$B$10000,$A40) -> 144.394 | D40: =SUMIFS(Fixed!D$2:D$10000,Fixed!$B$2:$B$10000,$A40) -> 144.394 | E40: =SUMIFS(Fixed!E$2:E$10000,Fixed!$B$2:$B$10000,$A40) -> 144.8195 | F40: =SUMIFS(Fixed!F$2:F$10000,Fixed!$B$2:$B$10000,$A40) -> 108.537 | G40: =SUMIFS(Fixed!G$2:G$10000,Fixed!$B$2:$B$10000,$A40) -> 108.537 | H40: =SUMIFS(Fixed!H$2:H$10000,Fixed!$B$2:$B$10000,$A40) -> 112.6425 | I40: =SUMIFS(Fixed!I$2:I$10000,Fixed!$B$2:$B$10000,$A40) -> 112.6425 | J40: =SUMIFS(Fixed!J$2:J$10000,Fixed!$B$2:$B$10000,$A40) -> 112.6425 | ... AG40: =SUMIFS(Fixed!AG$2:AG$10000,Fixed!$B$2:$B$10000,$A40) -> 13.892
A41: PHL_POW_PP_BIOM_CCS | C41: =SUMIFS(Fixed!C$2:C$10000,Fixed!$B$2:$B$10000,$A41) -> 0 | D41: =SUMIFS(Fixed!D$2:D$10000,Fixed!$B$2:$B$10000,$A41) -> 0 | E41: =SUMIFS(Fixed!E$2:E$10000,Fixed!$B$2:$B$10000,$A41) -> 0 | F41: =SUMIFS(Fixed!F$2:F$10000,Fixed!$B$2:$B$10000,$A41) -> 0 | G41: =SUMIFS(Fixed!G$2:G$10000,Fixed!$B$2:$B$10000,$A41) -> 0 | H41: =SUMIFS(Fixed!H$2:H$10000,Fixed!$B$2:$B$10000,$A41) -> 0 | I41: =SUMIFS(Fixed!I$2:I$10000,Fixed!$B$2:$B$10000,$A41) -> 0 | J41: =SUMIFS(Fixed!J$2:J$10000,Fixed!$B$2:$B$10000,$A41) -> 0 | ... AG41: =SUMIFS(Fixed!AG$2:AG$10000,Fixed!$B$2:$B$10000,$A41) -> 0
A42: PHL_POW_PP_COAL | C42: =SUMIFS(Fixed!C$2:C$10000,Fixed!$B$2:$B$10000,$A42) -> 0 | D42: =SUMIFS(Fixed!D$2:D$10000,Fixed!$B$2:$B$10000,$A42) -> 32.877 | E42: =SUMIFS(Fixed!E$2:E$10000,Fixed!$B$2:$B$10000,$A42) -> 67.7675 | F42: =SUMIFS(Fixed!F$2:F$10000,Fixed!$B$2:$B$10000,$A42) -> 67.7675 | G42: =SUMIFS(Fixed!G$2:G$10000,Fixed!$B$2:$B$10000,$A42) -> 94.9761 | H42: =SUMIFS(Fixed!H$2:H$10000,Fixed!$B$2:$B$10000,$A42) -> 94.9761 | I42: =SUMIFS(Fixed!I$2:I$10000,Fixed!$B$2:$B$10000,$A42) -> 94.9761 | J42: =SUMIFS(Fixed!J$2:J$10000,Fixed!$B$2:$B$10000,$A42) -> 124.4445 | ... AG42: =SUMIFS(Fixed!AG$2:AG$10000,Fixed!$B$2:$B$10000,$A42) -> 1503.4432
A43: PHL_POW_PP_COAL_CCS | C43: =SUMIFS(Fixed!C$2:C$10000,Fixed!$B$2:$B$10000,$A43) -> 0 | D43: =SUMIFS(Fixed!D$2:D$10000,Fixed!$B$2:$B$10000,$A43) -> 0 | E43: =SUMIFS(Fixed!E$2:E$10000,Fixed!$B$2:$B$10000,$A43) -> 0 | F43: =SUMIFS(Fixed!F$2:F$10000,Fixed!$B$2:$B$10000,$A43) -> 0 | G43: =SUMIFS(Fixed!G$2:G$10000,Fixed!$B$2:$B$10000,$A43) -> 0 | H43: =SUMIFS(Fixed!H$2:H$10000,Fixed!$B$2:$B$10000,$A43) -> 0 | I43: =SUMIFS(Fixed!I$2:I$10000,Fixed!$B$2:$B$10000,$A43) -> 0 | J43: =SUMIFS(Fixed!J$2:J$10000,Fixed!$B$2:$B$10000,$A43) -> 0 | ... AG43: =SUMIFS(Fixed!AG$2:AG$10000,Fixed!$B$2:$B$10000,$A43) -> 0
A44: PHL_POW_PP_H2 | C44: =SUMIFS(Fixed!C$2:C$10000,Fixed!$B$2:$B$10000,$A44) -> 0 | D44: =SUMIFS(Fixed!D$2:D$10000,Fixed!$B$2:$B$10000,$A44) -> 0 | E44: =SUMIFS(Fixed!E$2:E$10000,Fixed!$B$2:$B$10000,$A44) -> 0 | F44: =SUMIFS(Fixed!F$2:F$10000,Fixed!$B$2:$B$10000,$A44) -> 0 | G44: =SUMIFS(Fixed!G$2:G$10000,Fixed!$B$2:$B$10000,$A44) -> 0 | H44: =SUMIFS(Fixed!H$2:H$10000,Fixed!$B$2:$B$10000,$A44) -> 0 | I44: =SUMIFS(Fixed!I$2:I$10000,Fixed!$B$2:$B$10000,$A44) -> 0 | J44: =SUMIFS(Fixed!J$2:J$10000,Fixed!$B$2:$B$10000,$A44) -> 0 | ... AG44: =SUMIFS(Fixed!AG$2:AG$10000,Fixed!$B$2:$B$10000,$A44) -> 0
A45: PHL_POW_PP_HY_LA | C45: =SUMIFS(Fixed!C$2:C$10000,Fixed!$B$2:$B$10000,$A45) -> 191.6825 | D45: =SUMIFS(Fixed!D$2:D$10000,Fixed!$B$2:$B$10000,$A45) -> 191.6825 | E45: =SUMIFS(Fixed!E$2:E$10000,Fixed!$B$2:$B$10000,$A45) -> 192.2768 | F45: =SUMIFS(Fixed!F$2:F$10000,Fixed!$B$2:$B$10000,$A45) -> 194.0261 | G45: =SUMIFS(Fixed!G$2:G$10000,Fixed!$B$2:$B$10000,$A45) -> 195.3418 | H45: =SUMIFS(Fixed!H$2:H$10000,Fixed!$B$2:$B$10000,$A45) -> 195.3418 | I45: =SUMIFS(Fixed!I$2:I$10000,Fixed!$B$2:$B$10000,$A45) -> 195.3418 | J45: =SUMIFS(Fixed!J$2:J$10000,Fixed!$B$2:$B$10000,$A45) -> 195.3418 | ... AG45: =SUMIFS(Fixed!AG$2:AG$10000,Fixed!$B$2:$B$10000,$A45) -> 194.4896
A46: PHL_POW_PP_NGCC | C46: =SUMIFS(Fixed!C$2:C$10000,Fixed!$B$2:$B$10000,$A46) -> 0 | D46: =SUMIFS(Fixed!D$2:D$10000,Fixed!$B$2:$B$10000,$A46) -> 0 | E46: =SUMIFS(Fixed!E$2:E$10000,Fixed!$B$2:$B$10000,$A46) -> 0 | F46: =SUMIFS(Fixed!F$2:F$10000,Fixed!$B$2:$B$10000,$A46) -> 0 | G46: =SUMIFS(Fixed!G$2:G$10000,Fixed!$B$2:$B$10000,$A46) -> 0 | H46: =SUMIFS(Fixed!H$2:H$10000,Fixed!$B$2:$B$10000,$A46) -> 19.0192 | I46: =SUMIFS(Fixed!I$2:I$10000,Fixed!$B$2:$B$10000,$A46) -> 19.0192 | J46: =SUMIFS(Fixed!J$2:J$10000,Fixed!$B$2:$B$10000,$A46) -> 19.0192 | ... AG46: =SUMIFS(Fixed!AG$2:AG$10000,Fixed!$B$2:$B$10000,$A46) -> 194.0733
A47: PHL_POW_PP_NGCC_CCS | C47: =SUMIFS(Fixed!C$2:C$10000,Fixed!$B$2:$B$10000,$A47) -> 0 | D47: =SUMIFS(Fixed!D$2:D$10000,Fixed!$B$2:$B$10000,$A47) -> 0 | E47: =SUMIFS(Fixed!E$2:E$10000,Fixed!$B$2:$B$10000,$A47) -> 0 | F47: =SUMIFS(Fixed!F$2:F$10000,Fixed!$B$2:$B$10000,$A47) -> 0 | G47: =SUMIFS(Fixed!G$2:G$10000,Fixed!$B$2:$B$10000,$A47) -> 0 | H47: =SUMIFS(Fixed!H$2:H$10000,Fixed!$B$2:$B$10000,$A47) -> 0 | I47: =SUMIFS(Fixed!I$2:I$10000,Fixed!$B$2:$B$10000,$A47) -> 0 | J47: =SUMIFS(Fixed!J$2:J$10000,Fixed!$B$2:$B$10000,$A47) -> 0 | ... AG47: =SUMIFS(Fixed!AG$2:AG$10000,Fixed!$B$2:$B$10000,$A47) -> 0
A48: PHL_POW_PP_NU | C48: =SUMIFS(Fixed!C$2:C$10000,Fixed!$B$2:$B$10000,$A48) -> 0 | D48: =SUMIFS(Fixed!D$2:D$10000,Fixed!$B$2:$B$10000,$A48) -> 0 | E48: =SUMIFS(Fixed!E$2:E$10000,Fixed!$B$2:$B$10000,$A48) -> 0 | F48: =SUMIFS(Fixed!F$2:F$10000,Fixed!$B$2:$B$10000,$A48) -> 0 | G48: =SUMIFS(Fixed!G$2:G$10000,Fixed!$B$2:$B$10000,$A48) -> 0 | H48: =SUMIFS(Fixed!H$2:H$10000,Fixed!$B$2:$B$10000,$A48) -> 0 | I48: =SUMIFS(Fixed!I$2:I$10000,Fixed!$B$2:$B$10000,$A48) -> 0 | J48: =SUMIFS(Fixed!J$2:J$10000,Fixed!$B$2:$B$10000,$A48) -> 0 | ... AG48: =SUMIFS(Fixed!AG$2:AG$10000,Fixed!$B$2:$B$10000,$A48) -> 0
A49: PHL_POW_PP_NUSMR | C49: =SUMIFS(Fixed!C$2:C$10000,Fixed!$B$2:$B$10000,$A49) -> 0 | D49: =SUMIFS(Fixed!D$2:D$10000,Fixed!$B$2:$B$10000,$A49) -> 0 | E49: =SUMIFS(Fixed!E$2:E$10000,Fixed!$B$2:$B$10000,$A49) -> 0 | F49: =SUMIFS(Fixed!F$2:F$10000,Fixed!$B$2:$B$10000,$A49) -> 0 | G49: =SUMIFS(Fixed!G$2:G$10000,Fixed!$B$2:$B$10000,$A49) -> 0 | H49: =SUMIFS(Fixed!H$2:H$10000,Fixed!$B$2:$B$10000,$A49) -> 0 | I49: =SUMIFS(Fixed!I$2:I$10000,Fixed!$B$2:$B$10000,$A49) -> 0 | J49: =SUMIFS(Fixed!J$2:J$10000,Fixed!$B$2:$B$10000,$A49) -> 0 | ... AG49: =SUMIFS(Fixed!AG$2:AG$10000,Fixed!$B$2:$B$10000,$A49) -> 0
... A55: PHL_POW_TD | C55: =SUMIFS(Fixed!C$2:C$10000,Fixed!$B$2:$B$10000,$A55) -> 0 | D55: =SUMIFS(Fixed!D$2:D$10000,Fixed!$B$2:$B$10000,$A55) -> 0 | E55: =SUMIFS(Fixed!E$2:E$10000,Fixed!$B$2:$B$10000,$A55) -> 0 | F55: =SUMIFS(Fixed!F$2:F$10000,Fixed!$B$2:$B$10000,$A55) -> 0 | G55: =SUMIFS(Fixed!G$2:G$10000,Fixed!$B$2:$B$10000,$A55) -> 0 | H55: =SUMIFS(Fixed!H$2:H$10000,Fixed!$B$2:$B$10000,$A55) -> 0 | I55: =SUMIFS(Fixed!I$2:I$10000,Fixed!$B$2:$B$10000,$A55) -> 0 | J55: =SUMIFS(Fixed!J$2:J$10000,Fixed!$B$2:$B$10000,$A55) -> 0 | ... AG55: =SUMIFS(Fixed!AG$2:AG$10000,Fixed!$B$2:$B$10000,$A55) -> 0
A58: Capital Investments (M.USD) | C58: 2020 | D58: 2021 | E58: 2022 | F58: 2023 | G58: 2024 | H58: 2025 | I58: 2026 | J58: 2027 | K58: 2028 | L58: 2029 | M58: 2030 | N58: 2031 | O58: 2032 | P58: 2033 | Q58: 2034 | R58: 2035 | S58: 2036 | T58: 2037 | U58: 2038 | V58: 2039 | W58: 2040 | X58: 2041 | Y58: 2042 | Z58: 2043 | AA58: 2044 | AB58: 2045 | AC58: 2046 | AD58: 2047 | AE58: 2048 | AF58: 2049 | AG58: 2050
A59: PHL_POW_CHP_BIOM_OLD | C59: =SUMIFS(Capital_Investments!C$2:C$10000,Capital_Investments!$B$2:$B$10000,$A59) -> 0 | D59: =SUMIFS(Capital_Investments!D$2:D$10000,Capital_Investments!$B$2:$B$10000,$A59) -> 0 | E59: =SUMIFS(Capital_Investments!E$2:E$10000,Capital_Investments!$B$2:$B$10000,$A59) -> 820 | F59: =SUMIFS(Capital_Investments!F$2:F$10000,Capital_Investments!$B$2:$B$10000,$A59) -> 60 | G59: =SUMIFS(Capital_Investments!G$2:G$10000,Capital_Investments!$B$2:$B$10000,$A59) -> 99 | H59: =SUMIFS(Capital_Investments!H$2:H$10000,Capital_Investments!$B$2:$B$10000,$A59) -> 0 | I59: =SUMIFS(Capital_Investments!I$2:I$10000,Capital_Investments!$B$2:$B$10000,$A59) -> 0 | J59: =SUMIFS(Capital_Investments!J$2:J$10000,Capital_Investments!$B$2:$B$10000,$A59) -> 0 | ... AG59: =SUMIFS(Capital_Investments!AG$2:AG$10000,Capital_Investments!$B$2:$B$10000,$A59) -> 0
...

Sheet Variable
A1: REGION | B1: TECHNOLOGY | C1: 2020 | D1: 2021 | E1: 2022 | F1: 2023 | G1: 2024 | H1: 2025 | I1: 2026 | J1: 2027 | K1: 2028 | L1: 2029 | M1: 2030 | N1: 2031 | O1: 2032 | P1: 2033 | Q1: 2034 | R1: 2035 | S1: 2036 | T1: 2037 | U1: 2038 | V1: 2039 | W1: 2040 | X1: 2041 | Y1: 2042 | Z1: 2043 | AA1: 2044 | AB1: 2045 | AC1: 2046 | AD1: 2047 | AE1: 2048 | AF1: 2049 | AG1: 2050
B2: PHL_AGR_FAC | C2: 0.0009 | D2: 0.001 | E2: 0.001 | F2: 0.001 | G2: 0.001 | H2: 0.001 | I2: 0.0011 | J2: 0.0011 | K2: 0.0011 | L2: 0.0011 | M2: 0.0011 | N2: 0.0012 | O2: 0.0012 | P2: 0.0012 | Q2: 0.0013 | R2: 0.0013 | S2: 0.0013 | T2: 0.0013 | U2: 0.0014 | V2: 0.0014 | W2: 0.0014 | X2: 0.0011 | Y2: 0.001 | Z2: 0.001 | AA2: 0.0009 | AB2: 0.0008 | AC2: 0.0008 | AD2: 0.0007 | AE2: 0.0006 | AF2: 0.0006 | AG2: 0.0018 | AH2: 0.0019 | AI2: 0.0019 | AJ2: 0.0019 | AL2: 0.0394
B3: PHL_AGR_HEAT_BIOM | C3: 0 | D3: 0 | E3: 0 | F3: 0 | G3: 0 | H3: 0 | I3: 0 | J3: 0 | K3: 0 | L3: 0 | M3: 0 | N3: 0 | O3: 0 | P3: 0 | Q3: 0 | R3: 0 | S3: 0 | T3: 0 | U3: 0 | V3: 0 | W3: 0 | X3: 0 | Y3: 0 | Z3: 0 | AA3: 0 | AB3: 0 | AC3: 0 | AD3: 0 | AE3: 0 | AF3: 0 | AG3: 0 | AH3: 0 | AI3: 0 | AJ3: 0 | AL3: 0
B4: PHL_AGR_HEAT_COAL | C4: 0 | D4: 0 | E4: 0 | F4: 0 | G4: 0 | H4: 0 | I4: 0 | J4: 0 | K4: 0 | L4: 0 | M4: 0 | N4: 0 | O4: 0 | P4: 0 | Q4: 0 | R4: 0 | S4: 0 | T4: 0 | U4: 0 | V4: 0 | W4: 0 | X4: 0 | Y4: 0 | Z4: 0 | AA4: 0 | AB4: 0 | AC4: 0 | AD4: 0 | AE4: 0 | AF4: 0 | AG4: 0 | AH4: 0 | AI4: 0 | AJ4: 0 | AL4: 0
B5: PHL_AGR_HEAT_ELE | C5: 0 | D5: 0 | E5: 0 | F5: 0 | G5: 0 | H5: 0 | I5: 0 | J5: 0 | K5: 0 | L5: 0 | M5: 0 | N5: 0 | O5: 0 | P5: 0 | Q5: 0 | R5: 0 | S5: 0 | T5: 0 | U5: 0 | V5: 0 | W5: 0 | X5: 0 | Y5: 0 | Z5: 0 | AA5: 0 | AB5: 0 | AC5: 0 | AD5: 0 | AE5: 0 | AF5: 0 | AG5: 0 | AH5: 0 | AI5: 0 | AJ5: 0 | AL5: 0
B6: PHL_AGR_HEAT_NG | C6: 0.0008 | D6: 0.0008 | E6: 0.0008 | F6: 0.0008 | G6: 0.0009 | H6: 0.0009 | I6: 0.0009 | J6: 0.0009 | K6: 0.0009 | L6: 0.001 | M6: 0.001 | N6: 0.001 | O6: 0.001 | P6: 0.0011 | Q6: 0.0011 | R6: 0.0011 | S6: 0.0011 | T6: 0.0012 | U6: 0.0012 | V6: 0.0012 | W6: 0.0013 | X6: 0.0012 | Y6: 0.0011 | Z6: 0.001 | AA6: 0.0009 | AB6: 0.0009 | AC6: 0.0008 | AD6: 0.0008 | AE6: 0.0007 | AF6: 0.0006 | AG6: 0.0017 | AH6: 0.0018 | AI6: 0.0018 | AJ6: 0.0019 | AL6: 0.0362
B7: PHL_AGR_HEAT_OIL | C7: 0.0001 | D7: 0.0001 | E7: 0.0001 | F7: 0.0001 | G7: 0.0001 | H7: 0.0001 | I7: 0.0001 | J7: 0.0001 | K7: 0.0001 | L7: 0.0001 | M7: 0.0001 | N7: 0.0001 | O7: 0.0001 | P7: 0.0001 | Q7: 0.0001 | R7: 0.0001 | S7: 0.0001 | T7: 0.0001 | U7: 0.0001 | V7: 0.0001 | W7: 0.0001 | X7: 0 | Y7: 0.0001 | Z7: 0 | AA7: 0.0001 | AB7: 0 | AC7: 0 | AD7: 0 | AE7: 0 | AF7: 0 | AG7: 0 | AH7: 0 | AI7: 0 | AJ7: 0 | AL7: 0.0023
B8: PHL_AGR_MOT_ELE | C8: 0 | D8: 0 | E8: 0 | F8: 0 | G8: 0 | H8: 0 | I8: 0 | J8: 0 | K8: 0 | L8: 0 | M8: 0 | N8: 0 | O8: 0 | P8: 0 | Q8: 0 | R8: 0 | S8: 0 | T8: 0 | U8: 0 | V8: 0 | W8: 0 | X8: 0 | Y8: 0 | Z8: 0 | AA8: 0 | AB8: 0 | AC8: 0 | AD8: 0 | AE8: 0 | AF8: 0 | AG8: 0 | AH8: 0 | AI8: 0 | AJ8: 0 | AL8: 0
B9: PHL_AGR_MOT_LIQ | C9: 0.0008 | D9: 0.0008 | E9: 0.0008 | F9: 0.0008 | G9: 0.0009 | H9: 0.0009 | I9: 0.0009 | J9: 0.0009 | K9: 0.0009 | L9: 0.001 | M9: 0.001 | N9: 0.001 | O9: 0.001 | P9: 0.001 | Q9: 0.0011 | R9: 0.0011 | S9: 0.0011 | T9: 0.0011 | U9: 0.0012 | V9: 0.0012 | W9: 0.0012 | X9: 0.0012 | Y9: 0.0013 | Z9: 0.0013 | AA9: 0.0013 | AB9: 0.0014 | AC9: 0.0014 | AD9: 0.0014 | AE9: 0.0015 | AF9: 0.0015 | AG9: 0.0015 | AH9: 0.0016 | AI9: 0.0016 | AJ9: 0.0017 | AL9: 0.0394
B10: PHL_AGR_UNIT | C10: 0.0009 | D10: 0.001 | E10: 0.001 | F10: 0.001 | G10: 0.001 | H10: 0.001 | I10: 0.0011 | J10: 0.0011 | K10: 0.0011 | L10: 0.0011 | M10: 0.0011 | N10: 0.0012 | O10: 0.0012 | P10: 0.0012 | Q10: 0.0013 | R10: 0.0013 | S10: 0.0013 | T10: 0.0013 | U10: 0.0014 | V10: 0.0014 | W10: 0.0014 | X10: 0.0015 | Y10: 0.0015 | Z10: 0.0015 | AA10: 0.0016 | AB10: 0.0016 | AC10: 0.0016 | AD10: 0.0017 | AE10: 0.0017 | AF10: 0.0018 | AG10: 0.0018 | AH10: 0.0019 | AI10: 0.0019 | AJ10: 0.0019 | AL10: 0.0464
B11: PHL_DEM_PUB_GWT_WAT | C11: 0 | D11: 0 | E11: 0 | F11: 0 | G11: 0 | H11: 0 | I11: 0 | J11: 0 | K11: 0 | L11: 0 | M11: 0.0004 | N11: 0 | O11: 0 | P11: 0 | Q11: 0 | R11: 0 | S11: 0 | T11: 0 | U11: 0 | V11: 0 | W11: 0 | X11: 0 | Y11: 0.0003 | Z11: 0 | AA11: 0.0002 | AB11: 0.0004 | AC11: 0 | AD11: 0 | AE11: 0.0005 | AF11: 0.0006 | AG11: 0.0007 | AH11: 0.0002 | AI11: 0 | AJ11: 0.0009 | AL11: 0.0042
B12: PHL_DEM_PUB_SUR_WAT | C12: 0.002 | D12: 0.002 | E12: 0.0021 | F12: 0.0022 | G12: 0.0023 | H12: 0.0024 | I12: 0.0025 | J12: 0.0026 | K12: 0.0026 | L12: 0.0027 | M12: 0.0024 | N12: 0.003 | O12: 0.0031 | P12: 0.0032 | Q12: 0.0033 | R12: 0.0034 | S12: 0.0036 | T12: 0.0037 | U12: 0.0038 | V12: 0.004 | W12: 0.0041 | X12: 0.0043 | Y12: 0.0041 | Z12: 0.0046 | AA12: 0.0046 | AB12: 0.0046 | AC12: 0.0052 | AD12: 0.0053 | AE12: 0.005 | AF12: 0.0051 | AG12: 0.0052 | AH12: 0.006 | AI12: 0.0064 | AJ12: 0.0057 | AL12: 0.1271
B13: PHL_DEM_PWR_GWT_WAT | C13: 0.0003 | D13: 0.0003 | E13: 0.0002 | F13: 0.0005 | G13: 0.0002 | H13: 0.0005 | I13: 0.0005 | J13: 0.0003 | K13: 0.0005 | L13: 0.0005 | M13: 0.0001 | N13: 0.0005 | O13: 0.0005 | P13: 0.0005 | Q13: 0.0006 | R13: 0.0006 | S13: 0.0006 | T13: 0.0007 | U13: 0.0007 | V13: 0.0007 | W13: 0.0007 | X13: 0.0007 | Y13: 0.0004 | Z13: 0.0007 | AA13: 0.0006 | AB13: 0.0004 | AC13: 0.0008 | AD13: 0.0008 | AE13: 0.0003 | AF13: 0.0002 | AG13: 0.0002 | AH13: 0.0008 | AI13: 0.001 | AJ13: 0.0001 | AL13: 0.017
... B133: PHL_TRA_VAN_PHEV | C133: 0 | D133: 0 | E133: 0 | F133: 0 | G133: 0 | H133: 0 | I133: 0 | J133: 0 | K133: 0 | L133: 0 | M133: 0 | N133: 0 | O133: 0 | P133: 0 | Q133: 0 | R133: 0 | S133: 0 | T133: 0 | U133: 0 | V133: 0 | W133: 0 | X133: 0 | Y133: 0 | Z133: 0 | AA133: 0 | AB133: 0 | AC133: 0 | AD133: 0 | AE133: 0 | AF133: 0 | AG133: 0 | AH133: 0 | AI133: 0 | AJ133: 0 | AL133: 0
B134: (blank)

Sheet Fixed
A1: REGION | B1: TECHNOLOGY | C1: 2020 | D1: 2021 | E1: 2022 | F1: 2023 | G1: 2024 | H1: 2025 | I1: 2026 | J1: 2027 | K1: 2028 | L1: 2029 | M1: 2030 | N1: 2031 | O1: 2032 | P1: 2033 | Q1: 2034 | R1: 2035 | S1: 2036 | T1: 2037 | U1: 2038 | V1: 2039 | W1: 2040 | X1: 2041 | Y1: 2042 | Z1: 2043 | AA1: 2044 | AB1: 2045 | AC1: 2046 | AD1: 2047 | AE1: 2048 | AF1: 2049 | AG1: 2050
A2: REGION | B2: PHL_AGR_FAC | C2: 0 | D2: 0 | E2: 0 | F2: 0 | G2: 0 | H2: 0 | I2: 0 | J2: 0 | K2: 0 | L2: 0 | M2: 0 | N2: 0 | O2: 0 | P2: 0 | Q2: 0 | R2: 0 | S2: 0 | T2: 0 | U2: 0 | V2: 0 | W2: 0 | X2: 0 | Y2: 0 | Z2: 0 | AA2: 0 | AB2: 0 | AC2: 0 | AD2: 0 | AE2: 0 | AF2: 0 | AG2: 0 | AH2: 0 | AI2: 0 | AJ2: 0
A3: REGION | B3: PHL_AGR_HEAT_BIOM | C3: 0.1835 | D3: 0.1825 | E3: 0.182 | F3: 0.181 | G3: 0.1805 | H3: 0.1799 | I3: 0.1789 | J3: 0.1784 | K3: 0.1774 | L3: 0.1769 | M3: 0.1759 | N3: 0.1753 | O3: 0.1748 | P3: 0.1738 | Q3: 0.1733 | R3: 0.1723 | S3: 0.1719 | T3: 0.1714 | U3: 0.1705 | V3: 0.1701 | W3: 0.1688 | X3: 0.1682 | Y3: 0.1673 | Z3: 0.1669 | AA3: 0.1665 | AB3: 0 | AC3: 0 | AD3: 0 | AE3: 0 | AF3: 0 | AG3: 0 | AH3: 0 | AI3: 0 | AJ3: 0
A4: REGION | B4: PHL_AGR_HEAT_COAL | C4: 0 | D4: 0 | E4: 0 | F4: 0 | G4: 0 | H4: 0 | I4: 0 | J4: 0 | K4: 0 | L4: 0 | M4: 0 | N4: 0 | O4: 0 | P4: 0 | Q4: 0 | R4: 0 | S4: 0 | T4: 0 | U4: 0 | V4: 0 | W4: 0 | X4: 0 | Y4: 0 | Z4: 0 | AA4: 0 | AB4: 0 | AC4: 0 | AD4: 0 | AE4: 0 | AF4: 0 | AG4: 0 | AH4: 0 | AI4: 0 | AJ4: 0
A5: REGION | B5: PHL_AGR_HEAT_ELE | C5: 0 | D5: 0 | E5: 0 | F5: 0 | G5: 0 | H5: 0 | I5: 0 | J5: 0 | K5: 0 | L5: 0 | M5: 0 | N5: 0 | O5: 0 | P5: 0 | Q5: 0 | R5: 0 | S5: 0 | T5: 0 | U5: 0 | V5: 0 | W5: 0 | X5: 0 | Y5: 0 | Z5: 0 | AA5: 0 | AB5: 0 | AC5: 0 | AD5: 0 | AE5: 0 | AF5: 0 | AG5: 0 | AH5: 0 | AI5: 0 | AJ5: 0
A6: REGION | B6: PHL_AGR_HEAT_NG | C6: 2.4405 | D6: 2.5553 | E6: 2.6389 | F6: 2.7214 | G6: 2.8028 | H6: 2.8833 | I6: 2.9682 | J6: 3.0524 | K6: 3.1358 | L6: 3.2185 | M6: 3.396 | N6: 3.4797 | O6: 3.5634 | P6: 3.6471 | Q6: 3.7308 | R6: 3.8145 | S6: 3.914 | T6: 4.0135 | U6: 4.1129 | V6: 4.2124 | W6: 4.2799 | X6: 4.2759 | Y6: 4.2719 | Z6: 4.2677 | AA6: 4.2677 | AB6: 3.0437 | AC6: 2.9389 | AD6: 2.8669 | AE6: 2.7948 | AF6: 2.7228 | AG6: 5.8518 | AH6: 5.9963 | AI6: 6.1409 | AJ6: 6.2854
A7: REGION | B7: PHL_AGR_HEAT_OIL | C7: 0.4512 | D7: 0.4548 | E7: 0.458 | F7: 0.4608 | G7: 0.4633 | H7: 0.4654 | I7: 0.4673 | J7: 0.4688 | K7: 0.4702 | L7: 0.4714 | M7: 0.487 | N7: 0.4863 | O7: 0.4856 | P7: 0.4849 | Q7: 0.4842 | R7: 0.4835 | S7: 0.4828 | T7: 0.4822 | U7: 0.4815 | V7: 0.4808 | W7: 0.4801 | X7: 0.4794 | Y7: 0.478 | Z7: 0.478 | AA7: 0.478 | AB7: 0 | AC7: 0 | AD7: 0 | AE7: 0 | AF7: 0 | AG7: 0 | AH7: 0 | AI7: 0 | AJ7: 0
A8: REGION | B8: PHL_AGR_MOT_ELE | C8: 0 | D8: 0 | E8: 0 | F8: 0 | G8: 0 | H8: 0 | I8: 0 | J8: 0 | K8: 0 | L8: 0 | M8: 0 | N8: 0 | O8: 0 | P8: 0 | Q8: 0 | R8: 0 | S8: 0 | T8: 0 | U8: 0 | V8: 0 | W8: 0 | X8: 0 | Y8: 0 | Z8: 0 | AA8: 0 | AB8: 0 | AC8: 0 | AD8: 0 | AE8: 0 | AF8: 0 | AG8: 0 | AH8: 0 | AI8: 0 | AJ8: 0
A9: REGION | B9: PHL_AGR_MOT_LIQ | C9: 258.9921 | D9: 264.8225 | E9: 270.6529 | F9: 276.4833 | G9: 282.3137 | H9: 288.144 | I9: 294.4654 | J9: 300.7868 | K9: 307.1081 | L9: 313.4295 | M9: 319.7508 | N9: 326.9326 | O9: 334.1143 | P9: 341.296 | Q9: 348.4777 | R9: 355.6594 | S9: 364.2035 | T9: 372.7475 | U9: 381.2916 | V9: 389.8356 | W9: 398.3797 | X9: 408.3247 | Y9: 418.2698 | Z9: 428.2148 | AA9: 438.1599 | AB9: 448.105 | AC9: 459.4445 | AD9: 470.784 | AE9: 482.1235 | AF9: 493.463 | AG9: 504.8025 | AH9: 517.2698 | AI9: 529.737 | AJ9: 542.2043
A10: REGION | B10: PHL_AGR_UNIT | C10: 0 | D10: 0 | E10: 0 | F10: 0 | G10: 0 | H10: 0 | I10: 0 | J10: 0 | K10: 0 | L10: 0 | M10: 0 | N10: 0 | O10: 0 | P10: 0 | Q10: 0 | R10: 0 | S10: 0 | T10: 0 | U10: 0 | V10: 0 | W10: 0 | X10: 0 | Y10: 0 | Z10: 0 | AA10: 0 | AB10: 0 | AC10: 0 | AD10: 0 | AE10: 0 | AF10: 0 | AG10: 0 | AH10: 0 | AI10: 0 | AJ10: 0
A11: REGION | B11: PHL_DEM_PUB_GWT_WAT | C11: 0 | D11: 0 | E11: 0 | F11: 0 | G11: 0 | H11: 0 | I11: 0 | J11: 0 | K11: 0 | L11: 0 | M11: 0 | N11: 0 | O11: 0 | P11: 0 | Q11: 0 | R11: 0 | S11: 0 | T11: 0 | U11: 0 | V11: 0 | W11: 0 | X11: 0 | Y11: 0 | Z11: 0 | AA11: 0 | AB11: 0 | AC11: 0 | AD11: 0 | AE11: 0 | AF11: 0 | AG11: 0 | AH11: 0 | AI11: 0 | AJ11: 0
A12: REGION | B12: PHL_DEM_PUB_SUR_WAT | C12: 0 | D12: 0 | E12: 0 | F12: 0 | G12: 0 | H12: 0 | I12: 0 | J12: 0 | K12: 0 | L12: 0 | M12: 0 | N12: 0 | O12: 0 | P12: 0 | Q12: 0 | R12: 0 | S12: 0 | T12: 0 | U12: 0 | V12: 0 | W12: 0 | X12: 0 | Y12: 0 | Z12: 0 | AA12: 0 | AB12: 0 | AC12: 0 | AD12: 0 | AE12: 0 | AF12: 0 | AG12: 0 | AH12: 0 | AI12: 0 | AJ12: 0
A13: REGION | B13: PHL_DEM_PWR_GWT_WAT | C13: 0 | D13: 0 | E13: 0 | F13: 0 | G13: 0 | H13: 0 | I13: 0 | J13: 0 | K13: 0 | L13: 0 | M13: 0 | N13: 0 | O13: 0 | P13: 0 | Q13: 0 | R13: 0 | S13: 0 | T13: 0 | U13: 0 | V13: 0 | W13: 0 | X13: 0 | Y13: 0 | Z13: 0 | AA13: 0 | AB13: 0 | AC13: 0 | AD13: 0 | AE13: 0 | AF13: 0 | AG13: 0 | AH13: 0 | AI13: 0 | AJ13: 0
... A132: REGION | B132: PHL_TRA_VAN_NG | C132: 0 | D132: 0 | E132: 0 | F132: 0 | G132: 0 | H132: 0 | I132: 0 | J132: 0 | K132: 0 | L132: 0 | M132: 0 | N132: 0 | O132: 0 | P132: 0 | Q132: 0 | R132: 0 | S132: 0 | T132: 0 | U132: 0 | V132: 0 | W132: 0 | X132: 0 | Y132: 0 | Z132: 0 | AA132: 0 | AB132: 0 | AC132: 0 | AD132: 0 | AE132: 0 | AF132: 0 | AG132: 0 | AH132: 0 | AI132: 0 | AJ132: 0
B133: PHL_TRA_VAN_PHEV | C133: 0 | D133: 0 | E133: 0 | F133: 0 | G133: 0 | H133: 0 | I133: 0 | J133: 0 | K133: 0 | L133: 0 | M133: 0 | N133: 0 | O133: 0 | P133: 0 | Q133: 0 | R133: 0 | S133: 0 | T133: 0 | U133: 0 | V133: 0 | W133: 0 | X133: 0 | Y133: 0 | Z133: 0 | AA133: 0 | AB133: 0 | AC133: 0 | AD133: 0 | AE133: 0 | AF133: 0 | AG133: 0 | AH133: 0 | AI133: 0 | AJ133: 0
B134: (blank)

Sheet Capital_Investments
A1: Million USD
A2: REGION | B2: TECHNOLOGY | C2: 2020 | D2: 2021 | E2: 2022 | F2: 2023 | G2: 2024 | H2: 2025 | I2: 2026 | J2: 2027 | K2: 2028 | L2: 2029 | M2: 2030 | N2: 2031 | O2: 2032 | P2: 2033 | Q2: 2034 | R2: 2035 | S2: 2036 | T2: 2037 | U2: 2038 | V2: 2039 | W2: 2040 | X2: 2041 | Y2: 2042 | Z2: 2043 | AA2: 2044 | AB2: 2045 | AC2: 2046 | AD2: 2047 | AE2: 2048 | AF2: 2049 | AG2: 2050
A3: REGION | B3: PHL_AGR_FAC | C3: 0 | D3: 0 | E3: 0 | F3: 0 | G3: 0 | H3: 0 | I3: 0 | J3: 0 | K3: 0 | L3: 0 | M3: 0 | N3: 0 | O3: 0 | P3: 0 | Q3: 0 | R3: 0 | S3: 0 | T3: 0 | U3: 0 | V3: 0 | W3: 0 | X3: 0 | Y3: 0 | Z3: 0 | AA3: 0 | AB3: 0 | AC3: 0 | AD3: 0 | AE3: 0 | AF3: 0 | AG3: 0 | AH3: 0 | AI3: 0 | AJ3: 0
A4: REGION | B4: PHL_AGR_HEAT_BIOM | C4: 2.999 | D4: 0 | E4: 0 | F4: 0 | G4: 0 | H4: 0 | I4: 0 | J4: 0 | K4: 0 | L4: 0 | M4: 0 | N4: 0 | O4: 0 | P4: 0 | Q4: 0 | R4: 0 | S4: 0 | T4: 0 | U4: 0 | V4: 0 | W4: 0 | X4: 0 | Y4: 0 | Z4: 0 | AA4: 0 | AB4: 0 | AC4: 0 | AD4: 0 | AE4: 0 | AF4: 0 | AG4: 0 | AH4: 0 | AI4: 0 | AJ4: 0
A5: REGION | B5: PHL_AGR_HEAT_COAL | C5: 0 | D5: 0 | E5: 0 | F5: 0 | G5: 0 | H5: 0 | I5: 0 | J5: 0 | K5: 0 | L5: 0 | M5: 0 | N5: 0 | O5: 0 | P5: 0 | Q5: 0 | R5: 0 | S5: 0 | T5: 0 | U5: 0 | V5: 0 | W5: 0 | X5: 0 | Y5: 0 | Z5: 0 | AA5: 0 | AB5: 0 | AC5: 0 | AD5: 0 | AE5: 0 | AF5: 0 | AG5: 0 | AH5: 0 | AI5: 0 | AJ5: 0
A6: REGION | B6: PHL_AGR_HEAT_ELE | C6: 0 | D6: 0 | E6: 0 | F6: 0 | G6: 0 | H6: 0 | I6: 0 | J6: 0 | K6: 0 | L6: 0 | M6: 0 | N6: 0 | O6: 0 | P6: 0 | Q6: 0 | R6: 0 | S6: 0 | T6: 0 | U6: 0 | V6: 0 | W6: 0 | X6: 0 | Y6: 0 | Z6: 0 | AA6: 0 | AB6: 0 | AC6: 0 | AD6: 0 | AE6: 0 | AF6: 0 | AG6: 0 | AH6: 0 | AI6: 0 | AJ6: 0
A7: REGION | B7: PHL_AGR_HEAT_NG | C7: 47.1147 | D7: 1.9432 | E7: 1.3465 | F7: 1.3559 | G7: 1.3643 | H7: 1.372 | I7: 1.4878 | J7: 1.4944 | K7: 1.5004 | L7: 1.5058 | M7: 1.5544 | N7: 1.7539 | O7: 1.7539 | P7: 1.7539 | Q7: 1.7539 | R7: 1.7539 | S7: 2.0697 | T7: 2.0697 | U7: 2.0697 | V7: 2.0697 | W7: 1.4297 | X7: 0 | Y7: 0 | Z7: 0 | AA7: 0 | AB7: 26.7657 | AC7: 0 | AD7: 0 | AE7: 0 | AF7: 0 | AG7: 64.0209 | AH7: 4.4449 | AI7: 4.4449 | AJ7: 4.4449
A8: REGION | B8: PHL_AGR_HEAT_OIL | C8: 10.9168 | D8: 0 | E8: 0 | F8: 0 | G8: 0 | H8: 0 | I8: 0 | J8: 0 | K8: 0 | L8: 0 | M8: 0 | N8: 0 | O8: 0 | P8: 0 | Q8: 0 | R8: 0 | S8: 0 | T8: 0 | U8: 0 | V8: 0 | W8: 0 | X8: 0 | Y8: 0 | Z8: 0 | AA8: 0 | AB8: 0 | AC8: 0 | AD8: 0 | AE8: 0 | AF8: 0 | AG8: 0 | AH8: 0 | AI8: 0 | AJ8: 0
A9: REGION | B9: PHL_AGR_MOT_ELE | C9: 0 | D9: 0 | E9: 0 | F9: 0 | G9: 0 | H9: 0 | I9: 0 | J9: 0 | K9: 0 | L9: 0 | M9: 0 | N9: 0 | O9: 0 | P9: 0 | Q9: 0 | R9: 0 | S9: 0 | T9: 0 | U9: 0 | V9: 0 | W9: 0 | X9: 0 | Y9: 0 | Z9: 0 | AA9: 0 | AB9: 0 | AC9: 0 | AD9: 0 | AE9: 0 | AF9: 0 | AG9: 0 | AH9: 0 | AI9: 0 | AJ9: 0
A10: REGION | B10: PHL_AGR_MOT_LIQ | C10: 14270.519 | D10: 369.9875 | E10: 369.9875 | F10: 376.4785 | G10: 382.9696 | H10: 389.4606 | I10: 425.9008 | J10: 432.8827 | K10: 439.8647 | L10: 453.8287 | M10: 460.8106 | N10: 525.4367 | O10: 533.279 | P10: 533.279 | Q10: 498.5774 | R10: 17770.378 | S10: 1037.4189 | T10: 1037.4189 | U10: 1052.454 | V10: 1052.454 | W10: 1052.454 | X10: 1184.893 | Y10: 1201.82 | Z10: 1201.82 | AA10: 1201.82 | AB10: 1201.82 | AC10: 1361.9114 | AD10: 1361.9114 | AE10: 1381.0932 | AF10: 1336.6995 | AG10: 19359.448 | AH10: 1980.1654 | AI10: 1980.1653 | AJ10: 1980.1654
A11: REGION | B11: PHL_AGR_UNIT | C11: 0 | D11: 0 | E11: 0 | F11: 0 | G11: 0 | H11: 0 | I11: 0 | J11: 0 | K11: 0 | L11: 0 | M11: 0 | N11: 0 | O11: 0 | P11: 0 | Q11: 0 | R11: 0 | S11: 0 | T11: 0 | U11: 0 | V11: 0 | W11: 0 | X11: 0 | Y11: 0 | Z11: 0 | AA11: 0 | AB11: 0 | AC11: 0 | AD11: 0 | AE11: 0 | AF11: 0 | AG11: 0 | AH11: 0 | AI11: 0 | AJ11: 0
A12: REGION | B12: PHL_DEM_PUB_GWT_WAT | C12: 0 | D12: 0 | E12: 0 | F12: 0 | G12: 0 | H12: 0 | I12: 0 | J12: 0 | K12: 0 | L12: 0 | M12: 0 | N12: 0 | O12: 0 | P12: 0 | Q12: 0 | R12: 0 | S12: 0 | T12: 0 | U12: 0 | V12: 0 | W12: 0 | X12: 0 | Y12: 0 | Z12: 0 | AA12: 0 | AB12: 0 | AC12: 0 | AD12: 0 | AE12: 0 | AF12: 0 | AG12: 0 | AH12: 0 | AI12: 0 | AJ12: 0
A13: REGION | B13: PHL_DEM_PUB_SUR_WAT | C13: 0 | D13: 0 | E13: 0 | F13: 0 | G13: 0 | H13: 0 | I13: 0 | J13: 0 | K13: 0 | L13: 0 | M13: 0 | N13: 0 | O13: 0 | P13: 0 | Q13: 0 | R13: 0 | S13: 0 | T13: 0 | U13: 0 | V13: 0 | W13: 0 | X13: 0 | Y13: 0 | Z13: 0 | AA13: 0 | AB13: 0 | AC13: 0 | AD13: 0 | AE13: 0 | AF13: 0 | AG13: 0 | AH13: 0 | AI13: 0 | AJ13: 0
A14: REGION | B14: PHL_DEM_PWR_GWT_WAT | C14: 0 | D14: 0 | E14: 0 | F14: 0 | G14: 0 | H14: 0 | I14: 0 | J14: 0 | K14: 0 | L14: 0 | M14: 0 | N14: 0 | O14: 0 | P14: 0 | Q14: 0 | R14: 0 | S14: 0 | T14: 0 | U14: 0 | V14: 0 | W14: 0 | X14: 0 | Y14: 0 | Z14: 0 | AA14: 0 | AB14: 0 | AC14: 0 | AD14: 0 | AE14: 0 | AF14: 0 | AG14: 0 | AH14: 0 | AI14: 0 | AJ14: 0
... A133: REGION | B133: PHL_TRA_VAN_NG | C133: 0 | D133: 0 | E133: 0 | F133: 0 | G133: 0 | H133: 0 | I133: 0 | J133: 0 | K133: 0 | L133: 0 | M133: 0 | N133: 0 | O133: 0 | P133: 0 | Q133: 0 | R133: 0 | S133: 0 | T133: 0 | U133: 0 | V133: 0 | W133: 0 | X133: 0 | Y133: 0 | Z133: 0 | AA133: 0 | AB133: 0 | AC133: 0 | AD133: 0 | AE133: 0 | AF133: 0 | AG133: 0 | AH133: 0 | AI133: 0 | AJ133: 0
B134: PHL_TRA_VAN_PHEV | C134: 0 | D134: 0 | E134: 0 | F134: 0 | G134: 0 | H134: 0 | I134: 0 | J134: 0 | K134: 0 | L134: 0 | M134: 0 | N134: 0 | O134: 0 | P134: 0 | Q134: 0 | R134: 0 | S134: 0 | T134: 0 | U134: 0 | V134: 0 | W134: 0 | X134: 0 | Y134: 0 | Z134: 0 | AA134: 0 | AB134: 0 | AC134: 0 | AD134: 0 | AE134: 0 | AF134: 0 | AG134: 0 | AH134: 0 | AI134: 0 | AJ134: 0
B135: (blank)
A170: REGION | B170: GHA_PRO_BLEND_BIOF | C170: 0 | D170: 0 | E170: 0 | F170: 0 | G170: 0 | H170: 0 | I170: 0 | J170: 0 | K170: 0 | L170: 0 | M170: 0 | N170: 0 | O170: 0 | P170: 0 | Q170: 0 | R170: 0 | S170: 0 | T170: 0 | U170: 0 | V170: 0 | W170: 0 | X170: 0 | Y170: 0 | Z170: 0 | AA170: 0 | AB170: 0 | AC170: 0 | AD170: 0 | AE170: 0 | AF170: 0 | AG170: 0
A171: REGION | B171: GHA_PRO_BLEND_OIL | C171: 0 | D171: 0 | E171: 0 | F171: 0 | G171: 0 | H171: 0 | I171: 0 | J171: 0 | K171: 0 | L171: 0 | M171: 0 | N171: 0 | O171: 0 | P171: 0 | Q171: 0 | R171: 0 | S171: 0 | T171: 0 | U171: 0 | V171: 0 | W171: 0 | X171: 0 | Y171: 0 | Z171: 0 | AA171: 0 | AB171: 0 | AC171: 0 | AD171: 0 | AE171: 0 | AF171: 0 | AG171: 0
A172: REGION | B172: GHA_PRO_EXTR_COAL | C172: 0 | D172: 0 | E172: 0 | F172: 0 | G172: 0 | H172: 0 | I172: 0 | J172: 0 | K172: 0 | L172: 0 | M172: 0 | N172: 0 | O172: 0 | P172: 0 | Q172: 0 | R172: 0 | S172: 0 | T172: 0 | U172: 0 | V172: 0 | W172: 0 | X172: 0 | Y172: 0 | Z172: 0 | AA172: 0 | AB172: 0 | AC172: 0 | AD172: 0 | AE172: 0 | AF172: 0 | AG172: 0
A173: REGION | B173: GHA_PRO_EXTR_NG | C173: 0 | D173: 0 | E173: 0 | F173: 0 | G173: 0 | H173: 0 | I173: 0 | J173: 0 | K173: 0 | L173: 0 | M173: 0 | N173: 0 | O173: 0 | P173: 0 | Q173: 0 | R173: 0 | S173: 0 | T173: 0 | U173: 0 | V173: 0 | W173: 0 | X173: 0 | Y173: 0 | Z173: 0 | AA173: 0 | AB173: 0 | AC173: 0 | AD173: 0 | AE173: 0 | AF173: 0 | AG173: 0
A174: REGION | B174: GHA_PRO_EXTR_OIL | C174: 0 | D174: 0 | E174: 0 | F174: 0 | G174: 0 | H174: 0 | I174: 0 | J174: 0 | K174: 0 | L174: 0 | M174: 0 | N174: 0 | O174: 0 | P174: 0 | Q174: 0 | R174: 0 | S174: 0 | T174: 0 | U174: 0 | V174: 0 | W174: 0 | X174: 0 | Y174: 0 | Z174: 0 | AA174: 0 | AB174: 0 | AC174: 0 | AD174: 0 | AE174: 0 | AF174: 0 | AG174: 0
A175: REGION | B175: GHA_PRO_EXTR_UR | C175: 0 | D175: 0 | E175: 0 | F175: 0 | G175: 0 | H175: 0 | I175: 0 | J175: 0 | K175: 0 | L175: 0 | M175: 0 | N175: 0 | O175: 0 | P175: 0 | Q175: 0 | R175: 0 | S175: 0 | T175: 0 | U175: 0 | V175: 0 | W175: 0 | X175: 0 | Y175: 0 | Z175: 0 | AA175: 0 | AB175: 0 | AC175: 0 | AD175: 0 | AE175: 0 | AF175: 0 | AG175: 0
A176: REGION | B176: GHA_PRO_PROC_BIOF1 | C176: 0 | D176: 0 | E176: 0 | F176: 0 | G176: 0 | H176: 0 | I176: 0 | J176: 0 | K176: 0 | L176: 0 | M176: 0 | N176: 0 | O176: 0 | P176: 0 | Q176: 0 | R176: 0 | S176: 0 | T176: 0 | U176: 0 | V176: 0 | W176: 0 | X176: 0 | Y176: 0 | Z176: 0 | AA176: 0 | AB176: 0 | AC176: 0 | AD176: 0 | AE176: 0 | AF176: 8.93e-05 | AG176: 132.77715
A177: REGION | B177: GHA_PRO_PROC_BIOM | C177: 0 | D177: 0 | E177: 0 | F177: 0 | G177: 0 | H177: 0 | I177: 0 | J177: 0 | K177: 0 | L177: 0 | M177: 0 | N177: 0 | O177: 0 | P177: 0 | Q177: 0 | R177: 0 | S177: 0 | T177: 0 | U177: 0 | V177: 0 | W177: 0 | X177: 0 | Y177: 0 | Z177: 0 | AA177: 0 | AB177: 0 | AC177: 0 | AD177: 0 | AE177: 0 | AF177: 0 | AG177: 0
A178: REGION | B178: GHA_PRO_PROC_COAL | C178: 0 | D178: 0 | E178: 0 | F178: 0 | G178: 0 | H178: 0 | I178: 0 | J178: 0 | K178: 0 | L178: 0 | M178: 0 | N178: 0 | O178: 0 | P178: 0 | Q178: 0 | R178: 0 | S178: 0 | T178: 0 | U178: 0 | V178: 0 | W178: 0 | X178: 0 | Y178: 0 | Z178: 0 | AA178: 0 | AB178: 0 | AC178: 0 | AD178: 0 | AE178: 0 | AF178: 0 | AG178: 0
A179: REGION | B179: GHA_PRO_PROC_NG | C179: 0 | D179: 0 | E179: 0 | F179: 0 | G179: 0 | H179: 0 | I179: 0 | J179: 0 | K179: 0 | L179: 0 | M179: 0 | N179: 0 | O179: 0 | P179: 0 | Q179: 0 | R179: 0 | S179: 0 | T179: 0 | U179: 0 | V179: 0 | W179: 0 | X179: 0 | Y179: 0 | Z179: 0 | AA179: 0 | AB179: 0 | AC179: 0 | AD179: 0 | AE179: 0 | AF179: 0 | AG179: 0
A180: REGION | B180: GHA_PRO_PROC_OIL | C180: 0 | D180: 0 | E180: 0 | F180: 0 | G180: 0 | H180: 0 | I180: 0 | J180: 0 | K180: 0 | L180: 0 | M180: 0 | N180: 0 | O180: 0 | P180: 0 | Q180: 0 | R180: 0 | S180: 0 | T180: 0 | U180: 0 | V180: 0 | W180: 0 | X180: 0 | Y180: 0 | Z180: 0 | AA180: 0 | AB180: 0 | AC180: 0 | AD180: 0 | AE180: 0 | AF180: 0 | AG180: 0
A181: REGION | B181: GHA_PRO_PROC_TRADBIOM | C181: 0 | D181: 0 | E181: 0 | F181: 0 | G181: 0 | H181: 0 | I181: 0 | J181: 0 | K181: 0 | L181: 0 | M181: 0 | N181: 0 | O181: 0 | P181: 0 | Q181: 0 | R181: 0 | S181: 0 | T181: 0 | U181: 0 | V181: 0 | W181: 0 | X181: 0 | Y181: 0 | Z181: 0 | AA181: 0 | AB181: 0 | AC181: 0 | AD181: 0 | AE181: 0 | AF181: 0 | AG181: 0
... A220: REGION | B220: SLE_POST_UNIT | C220: 0 | D220: 0 | E220: 0 | F220: 0 | G220: 0 | H220: 0 | I220: 0 | J220: 0 | K220: 0 | L220: 0 | M220: 0 | N220: 0 | O220: 0 | P220: 0 | Q220: 0 | R220: 0 | S220: 0 | T220: 0 | U220: 0 | V220: 0 | W220: 0 | X220: 0 | Y220: 0 | Z220: 0 | AA220: 0 | AB220: 0 | AC220: 0 | AD220: 0 | AE220: 0 | AF220: 0 | AG220: 0

Sheet Annualized_Investments
A1: Million USD
B2: Year | C2: 2020 | D2: 2021 | E2: 2022 | F2: 2023 | G2: 2024 | H2: 2025 | I2: 2026 | J2: 2027 | K2: 2028 | L2: 2029 | M2: 2030 | N2: 2031 | O2: 2032 | P2: 2033 | Q2: 2034 | R2: 2035 | S2: 2036 | T2: 2037 | U2: 2038 | V2: 2039 | W2: 2040 | X2: 2041 | Y2: 2042 | Z2: 2043 | AA2: 2044 | AB2: 2045 | AC2: 2046 | AD2: 2047 | AE2: 2048 | AF2: 2049 | AG2: 2050 | AH2: 2051 | AI2: 2052 | AJ2: 2053
B3: PHL_AGR_HEAT_BIOM | C3: 0.20265373 | D3: 0.20265373 | E3: 0.20265373 | F3: 0.20265373 | G3: 0.20265373 | H3: 0.20265373 | I3: 0.20265373 | J3: 0.20265373 | K3: 0.20265373 | L3: 0.20265373 | M3: 0.20265373 | N3: 0.20265373 | O3: 0.20265373 | P3: 0.20265373 | Q3: 0.20265373 | R3: 0.20265373 | S3: 0.20265373 | T3: 0.20265373 | U3: 0.20265373 | V3: 0.20265373 | W3: 0.20265373 | X3: 0.20265373 | Y3: 0.20265373 | Z3: 0.20265373 | AA3: 0.20265373
B4: PHL_AGR_HEAT_NG | C4: 3.1837178 | D4: 3.3150272 | E4: 3.4060153 | F4: 3.4976385 | G4: 3.5898294 | H4: 3.6825407 | I4: 3.7830769 | J4: 3.8840591 | K4: 3.9854468 | L4: 4.0871994 | M4: 4.1922361 | N4: 4.3107537 | O4: 4.4292713 | P4: 4.547789 | Q4: 4.6663066 | R4: 4.7848242 | S4: 4.9246817 | T4: 5.0645391 | U4: 5.2043965 | V4: 5.344254 | W4: 5.4408642 | X4: 5.4408642 | Y4: 5.4408642 | Z4: 5.4408642 | AA4: 5.4408642 | AB4: 4.0658056 | AC4: 3.9344962 | AD4: 3.8435081 | AE4: 3.7518849 | AF4: 3.659694 | AG4: 7.8931162 | AH4: 8.0929386 | AI4: 8.292315 | AJ4: 8.491286
B5: PHL_AGR_HEAT_OIL | C5: 0.73768932 | D5: 0.73768932 | E5: 0.73768932 | F5: 0.73768932 | G5: 0.73768932 | H5: 0.73768932 | I5: 0.73768932 | J5: 0.73768932 | K5: 0.73768932 | L5: 0.73768932 | M5: 0.73768932 | N5: 0.73768932 | O5: 0.73768932 | P5: 0.73768932 | Q5: 0.73768932 | R5: 0.73768932 | S5: 0.73768932 | T5: 0.73768932 | U5: 0.73768932 | V5: 0.73768932 | W5: 0.73768932 | X5: 0.73768932 | Y5: 0.73768932 | Z5: 0.73768932 | AA5: 0.73768932
B6: PHL_AGR_MOT_LIQ | C6: 1309.3852 | D6: 1343.3332 | E6: 1377.2813 | F6: 1411.8249 | G6: 1446.9641 | H6: 1482.6989 | I6: 1521.7772 | J6: 1561.4962 | K6: 1601.8558 | L6: 1643.4966 | M6: 1685.7781 | N6: 1733.9893 | O6: 1782.9201 | P6: 1831.8509 | Q6: 1877.5976 | R6: 2198.7256 | S6: 2259.9655 | T6: 2321.2054 | U6: 2383.2292 | V6: 2444.6575 | W6: 2505.4901 | X6: 2575.1311 | Y6: 2645.6846 | Z6: 2715.5975 | AA6: 2784.2291 | AB6: 2852.2201 | AC6: 2928.9705 | AD6: 3005.0013 | AE6: 3082.7921 | AF6: 3159.6936 | AG6: 3305.498 | AH6: 3391.9993 | AI6: 3478.5006 | AJ6: 3563.6224
B7: PHL_HOU_COOK_BIOM | C7: 2083.34 | D7: 2083.34 | E7: 2083.34 | F7: 2083.34 | G7: 2083.34 | H7: 2083.34 | I7: 2083.34 | J7: 2083.34 | K7: 2083.34 | L7: 2083.34 | M7: 2083.34 | N7: 2083.34 | O7: 2083.34 | P7: 2083.34 | Q7: 2083.34
B8: PHL_HOU_COOK_COAL | D8: 2208.019 | E8: 2241.5777 | F8: 2296.9071 | G8: 2338.3289 | H8: 2372.106 | I8: 2407.9074 | J8: 2441.3928 | K8: 2483.2534 | L8: 2498.9036 | M8: 2527.0201 | N8: 2561.715 | O8: 2584.1201 | P8: 2613.7796 | Q8: 2642.8012 | R8: 2752.3885 | S8: 2778.612 | T8: 2804.8354 | U8: 2831.068 | V8: 2857.2915 | W8: 2883.5241 | X8: 2906.8206 | Y8: 2930.117 | Z8: 2953.4135 | AA8: 2976.71 | AB8: 3000.0157 | AC8: 3020.1741 | AD8: 3040.3326 | AE8: 3060.4911 | AF8: 3080.6587 | AG8: 3100.8172 | AH8: 3118.2139 | AI8: 3135.6013 | AJ8: 3152.998
B9: PHL_HOU_COOK_ELE | C9: 101.97367 | D9: 101.97367 | E9: 101.97367 | F9: 101.97367 | G9: 101.97367 | H9: 101.97367 | I9: 101.97367 | J9: 101.97367 | K9: 101.97367 | L9: 101.97367 | M9: 101.97367 | N9: 101.97367 | O9: 101.97367 | P9: 101.97367 | Q9: 101.97367
B10: PHL_INDU_OTHHPH_BIOM | C10: 23.647988 | D10: 23.647988 | E10: 23.647988 | F10: 23.647988 | G10: 23.647988 | H10: 23.647988 | I10: 23.647988 | J10: 23.647988 | K10: 23.647988 | L10: 23.647988 | M10: 23.647988 | N10: 23.647988 | O10: 23.647988 | P10: 23.647988 | Q10: 23.647988 | R10: 23.647988 | S10: 23.647988 | T10: 23.647988 | U10: 23.647988 | V10: 23.647988 | W10: 23.647988 | X10: 23.647988 | Y10: 23.647988 | Z10: 23.647988 | AA10: 23.647988
B11: PHL_INDU_OTHHPH_COAL | C11: 46.682345 | D11: 137.70501 | E11: 140.83673 | F11: 143.9507 | G11: 147.04756 | H11: 150.12794 | I11: 153.44366 | J11: 156.74292 | K11: 160.02638 | L11: 163.29472 | M11: 166.51787 | N11: 170.15337 | O11: 173.77412 | P11: 177.38088 | Q11: 180.97443 | R11: 184.55551 | S11: 188.78726 | T11: 193.00596 | U11: 197.21242 | V11: 201.40743 | W11: 205.55182 | X11: 210.35264 | Y11: 215.14384 | Z11: 219.92939 | AA11: 224.6288 | AB11: 224.25299 | AC11: 220.13046 | AD11: 225.46746 | AE11: 230.20299 | AF11: 235.24561 | AG11: 240.23367 | AH11: 245.74004 | AI11: 251.26288 | AJ11: 256.80151
B12: PHL_INDU_OTHHPH_NG | C12: 0.2391233 | D12: 0.2391233 | E12: 0.2391233 | F12: 0.2391233 | G12: 0.2391233 | H12: 0.2391233 | I12: 0.2391233 | J12: 0.2391233 | K12: 0.2391233 | L12: 0.2391233 | M12: 0.2391233 | N12: 0.2391233 | O12: 0.2391233 | P12: 0.2391233 | Q12: 0.2391233 | R12: 0.2391233 | S12: 0.2391233 | T12: 0.2391233 | U12: 0.2391233 | V12: 0.2391233 | W12: 0.2391233 | X12: 0.2391233 | Y12: 0.2391233 | Z12: 0.2391233 | AA12: 0.2391233
B13: PHL_INDU_OTHHPH_OIL | C13: 30.260845 | D13: 30.260845 | E13: 30.260845 | F13: 30.260845 | G13: 30.260845 | H13: 30.260845 | I13: 30.260845 | J13: 30.260845 | K13: 30.260845 | L13: 30.260845 | M13: 30.260845 | N13: 30.260845 | O13: 30.260845 | P13: 30.260845 | Q13: 30.260845 | R13: 30.260845 | S13: 30.260845 | T13: 30.260845 | U13: 30.260845 | V13: 30.260845 | W13: 30.260845 | X13: 30.260845 | Y13: 30.260845 | Z13: 30.260845 | AA13: 30.260845
B14: PHL_INDU_OTHLPH_BIOM | C14: 23.647988 | D14: 23.647988 | E14: 23.647988 | F14: 23.647988 | G14: 23.647988 | H14: 23.647988 | I14: 23.647988 | J14: 23.647988 | K14: 23.647988 | L14: 23.647988 | M14: 23.647988 | N14: 23.647988 | O14: 23.647988 | P14: 23.647988 | Q14: 23.647988 | R14: 23.647988 | S14: 23.647988 | T14: 23.647988 | U14: 23.647988 | V14: 23.647988 | W14: 23.647988 | X14: 23.647988 | Y14: 23.647988 | Z14: 23.647988 | AA14: 23.647988
B15: PHL_INDU_OTHLPH_COAL | C15: 46.682345 | D15: 137.70501 | E15: 140.83673 | F15: 143.9507 | G15: 147.04756 | H15: 150.12794 | I15: 153.44366 | J15: 156.74292 | K15: 160.02638 | L15: 163.29472 | M15: 166.51787 | N15: 170.15337 | O15: 173.77412 | P15: 177.38088 | Q15: 180.97443 | R15: 184.55551 | S15: 188.78726 | T15: 193.00596 | U15: 197.21242 | V15: 201.40743 | W15: 205.55182 | X15: 210.35264 | Y15: 215.14384 | Z15: 219.92939 | AA15: 224.6288 | AB15: 223.21648 | AC15: 226.03197 | AD15: 229.3487 | AE15: 233.34245 | AF15: 237.10246 | AG15: 240.76432 | AH15: 245.40163 | AI15: 250.92447 | AJ15: 256.4631
B16: PHL_INDU_OTHLPH_NG | C16: 0.21971611 | D16: 0.21971611 | E16: 0.21971611 | F16: 0.21971611 | G16: 0.21971611 | H16: 0.21971611 | I16: 0.21971611 | J16: 0.21971611 | K16: 0.21971611 | L16: 0.21971611 | M16: 0.21971611 | N16: 0.21971611 | O16: 0.21971611 | P16: 0.21971611 | Q16: 0.21971611 | R16: 0.21971611 | S16: 0.21971611 | T16: 0.21971611 | U16: 0.21971611 | V16: 0.21971611 | W16: 0.21971611 | X16: 0.21971611 | Y16: 0.21971611 | Z16: 0.21971611 | AA16: 0.21971611
B17: PHL_INDU_OTHLPH_OIL | C17: 34.242722 | D17: 34.242722 | E17: 34.242722 | F17: 34.242722 | G17: 34.242722 | H17: 34.242722 | I17: 34.242722 | J17: 34.242722 | K17: 34.242722 | L17: 34.242722 | M17: 34.242722 | N17: 34.242722 | O17: 34.242722 | P17: 34.242722 | Q17: 34.242722 | R17: 34.242722 | S17: 34.242722 | T17: 34.242722 | U17: 34.242722 | V17: 34.242722
B18: PHL_POW_CHP_BIOM_OLD | E18: 45.512469 | F18: 48.842649 | G18: 54.337447 | H18: 54.337447 | I18: 54.337447 | J18: 54.337447 | K18: 54.337447 | L18: 54.337447 | M18: 54.337447 | N18: 54.337447 | O18: 54.337447 | P18: 54.337447 | Q18: 54.337447 | R18: 54.337447 | S18: 54.337447 | T18: 54.337447 | U18: 54.337447 | V18: 54.337447 | W18: 54.337447 | X18: 54.337447 | Y18: 54.337447 | Z18: 54.337447 | AA18: 54.337447 | AB18: 54.337447 | AC18: 54.337447 | AD18: 54.337447 | AE18: 54.337447 | AF18: 54.337447 | AG18: 54.337447 | AH18: 54.337447 | AI18: 54.337447 | AJ18: 54.337447
B19: PHL_POW_CHP_OIL_OLD | D19: 99.794413 | E19: 153.79884 | F19: 153.79884 | G19: 160.01518 | H19: 160.01518 | I19: 160.01518 | J19: 160.01518 | K19: 160.01518 | L19: 160.01518 | M19: 160.01518 | N19: 160.01518 | O19: 160.01518 | P19: 160.01518 | Q19: 160.01518 | R19: 160.01518 | S19: 160.01518 | T19: 160.01518 | U19: 160.01518 | V19: 160.01518 | W19: 160.01518 | X19: 160.01518 | Y19: 160.01518 | Z19: 160.01518 | AA19: 160.01518 | AB19: 160.01518 | AC19: 160.01518 | AD19: 160.01518 | AE19: 160.01518 | AF19: 160.01518 | AG19: 160.01518 | AH19: 160.01518 | AI19: 160.01518 | AJ19: 160.01518
B20: PHL_POW_GEO_OLD | E20: 2.0536114 | F20: 2.0536114 | G20: 2.0536114 | H20: 21.868186 | I20: 21.868186 | J20: 21.868186 | K20: 21.868186 | L20: 21.868186 | M20: 21.868186 | N20: 21.868186 | O20: 21.868186 | P20: 21.868186 | Q20: 21.868186 | R20: 21.868186 | S20: 21.868186 | T20: 21.868186 | U20: 21.868186 | V20: 21.868186 | W20: 21.868186 | X20: 21.868186 | Y20: 21.868186 | Z20: 21.868186 | AA20: 21.868186 | AB20: 21.868186 | AC20: 21.868186 | AD20: 21.868186 | AE20: 21.868186 | AF20: 21.868186 | AG20: 21.868186 | AH20: 21.868186 | AI20: 21.868186 | AJ20: 21.868186
B21: PHL_POW_PP_COAL | D21: 76.300543 | E21: 157.27384 | F21: 157.27384 | G21: 220.41912 | H21: 220.41912 | I21: 220.41912 | J21: 288.80896 | K21: 340.51505 | L21: 669.18394 | M21: 734.33536 | N21: 808.93657 | O21: 1020.5949 | P21: 1139.182 | Q21: 1266.5553 | R21: 1391.2376 | S21: 1630.0599 | T21: 1841.2372 | U21: 2051.163 | V21: 2262.5834 | W21: 2262.5834 | X21: 2262.5834 | Y21: 2262.5834 | Z21: 2262.5834 | AA21: 2262.5834 | AB21: 2275.7998 | AC21: 2199.4992 | AD21: 2118.5259 | AE21: 2098.0278 | AF21: 2034.8825 | AG21: 2021.1857 | AH21: 1858.2996 | AI21: 1747.5721 | AJ21: 1734.7027
B22: PHL_POW_PP_HY_LA | C22: 119.29659 | D22: 119.29659 | E22: 120.59284 | F22: 124.40819 | G22: 127.27786 | H22: 127.27786 | I22: 127.27786 | J22: 127.27786 | K22: 127.27786 | L22: 127.27786 | M22: 127.27786 | N22: 127.27786 | O22: 127.27786 | P22: 127.27786 | Q22: 127.27786 | R22: 127.27786 | S22: 127.27786 | T22: 127.27786 | U22: 127.27786 | V22: 127.27786 | W22: 127.27786 | X22: 127.27786 | Y22: 127.27786 | Z22: 127.27786 | AA22: 127.27786 | AB22: 127.27786 | AC22: 127.27786 | AD22: 127.27786 | AE22: 127.27786 | AF22: 127.27786 | AG22: 127.27786 | AH22: 127.27786 | AI22: 127.27786 | AJ22: 127.27786
B23: PHL_POW_PP_NGCC | H23: 39.669519 | I23: 39.669519 | J23: 39.669519 | K23: 39.669519 | L23: 39.669519 | M23: 39.669519 | N23: 39.669519 | O23: 39.669519 | P23: 39.669519 | Q23: 39.669519 | R23: 39.669519 | S23: 39.669519 | T23: 39.669519 | U23: 39.669519 | V23: 75.660957 | W23: 89.31102 | X23: 89.31102 | Y23: 89.31102 | Z23: 89.31102 | AA23: 89.31102 | AB23: 182.7285 | AC23: 182.7285 | AD23: 182.7285 | AE23: 182.7285 | AF23: 182.7285 | AG23: 300.29201 | AH23: 332.49584 | AI23: 332.49584 | AJ23: 334.05845
B24: PHL_POW_PP_SPV_T1 | D24: 17.87676 | E24: 35.182747 | F24: 43.737239 | G24: 96.293446 | H24: 110.19144 | I24: 110.19144 | J24: 110.19144 | K24: 110.19144 | L24: 110.19144 | M24: 373.66013 | N24: 373.66013 | O24: 373.66013 | P24: 373.66013 | Q24: 448.99732 | R24: 448.99732 | S24: 448.99732 | T24: 448.99732 | U24: 448.99732 | V24: 448.99732 | W24: 1178.7439 | X24: 1178.7439 | Y24: 1180.0775 | Z24: 1181.3251 | AA24: 1182.4248 | AD24: 62.764779 | AE24: 130.86508 | AF24: 317.39635 | AG24: 2553.4477 | AH24: 2945.8834 | AI24: 3445.2015 | AJ24: 3716.6355
B25: PHL_POW_PP_WON_T1 | C25: 24.191247 | D25: 24.191247 | E25: 24.191247 | F25: 24.191247 | G25: 24.191247 | H25: 24.191247 | I25: 24.191247 | J25: 24.191247 | K25: 24.191247 | L25: 24.191247 | M25: 24.191247 | N25: 24.191247 | O25: 24.191247 | P25: 24.191247 | Q25: 24.191247 | R25: 24.191247 | S25: 24.191247 | T25: 24.191247 | U25: 24.191247 | V25: 24.191247 | W25: 24.191247 | X25: 24.191247 | Y25: 24.191247 | Z25: 24.191247 | AA25: 24.191247 | AB25: 2222.151 | AC25: 2255.2683 | AD25: 2255.2683 | AE25: 2307.6895 | AF25: 2310.3359 | AG25: 2361.3286 | AH25: 2343.4518 | AI25: 2326.1458 | AJ25: 2367.9285
